Workbook

Sheet Read Me
A1: DisruptRadar — Reconciled Financial Model
A2: Snapshot | B2: Exported from the Base scenario on 12 October 2026; the Year 1 projection covers January–December 2027.
A3: Approved Plan | B3: Pro price: €99/month; 10 average domains × €3/domain/month; Base fixed costs: €500/month; opening cash: €20,000.
A4: Pessimistic | B4: Revenue: €8,000; costs: €6,000; EBITDA: €2,000. The monthly customer curve is missing; do not infer cost coverage from 12 customers at year-end.
A5: Base | B5: Revenue: €30,096; delivery costs: €9,120; fixed costs: €6,000; total costs: €15,120; EBITDA: €14,976; minimum monthly cash: €19,345; closing cash: €34,976.
A6: Conditional Optimistic Case | B6: Revenue: €80,000; costs: €24,000; EBITDA: €56,000. Requires an effective cost of €2.59875/domain/month with annual fixed costs of €3,000; the required 13.375% discount is unvalidated. Uses Pro-equivalent volumes, with no Enterprise mix.
A7: Gross Margins | B7: 75% / 80% / 85% are independent assumptions that still need validation, not margins substantiated by delivery costs.
A8: Cash Coverage with Zero Revenue | B8: 40 / 15.8730 / 10 months; opening cash divided by average monthly costs. This is not a forecast of when cash will run out.
A9: How to Use the Excel Simulator | B9: Edit the five yellow cells B5:B9. Demand loss is a percentage (10% = 0.10). Revenue and delivery costs fall with demand; fixed costs remain unchanged. This does not alter the native worksheets or the Model.
A10: Native Tables | B10: Native export of all visible tables on both pages in the Base scenario, including scenario comparisons, sensitivities and thresholds. Formulas and cross-worksheet links have been preserved.
A11: Canvas and Text | B11: The web simulator and narrative text are not included in the native export. This worksheet and the Excel Simulator were added to document the assumptions and enable local testing.
A12: Whole Customer-Month Break-Even | B12: With annual fixed costs of €6,000 and delivery costs of €30 per customer-month: whole customer-month minimums are 87 / 76 / 68 at prices of €99 / €109 / €119.
A13: Price Indifference | B13: At €109: 265.51899 customer-months and maximum demand loss of 12.65823%. At €119: 235.68539 customer-months and 22.47191%. Fixed costs and unit delivery costs are the same as in the Base case.
... A16: Repository | B16: Authorised destination: public repository NUNRIBHAC/Neathack-Agent, main branch, docs/DisruptRadar_Modelo_Financeiro.xlsx. Public publication was authorised on 12 October 2026. Publication status is confirmed separately in the chat.
A19: Worksheet Index
A20: Read Me | B20: DisruptRadar — Reconciled Financial Model
A21: Excel Simulator | B21: DisruptRadar — Demand Loss, Price and Cash
A22: Scenario Matrix | B22: DisruptRadar Business Plan · DisruptRadar Scenario Matrix
A23: Year 1 Assumptions | B23: DisruptRadar Business Plan · DisruptRadar Assumptions — Year 1
A24: Usage-Based Delivery Costs | B24: DisruptRadar Business Plan · Usage-Based Delivery Costs — Pro Reference
A25: Base Projection Controls | B25: DisruptRadar — Monthly Projection · Base Projection Controls
A26: Base Monthly Projection | B26: DisruptRadar — Monthly Projection · Base Monthly Projection — Customers, Earnings and Cash
A27: Base Annual Reconciliation | B27: DisruptRadar — Monthly Projection · Base Annual Reconciliation with the Scenario Matrix
A28: Fixed Cost Sensitivity | B28: DisruptRadar — Monthly Projection · Base Sensitivity — Monthly Fixed Costs
A29: Price & Fixed Cost Sensitivity | B29: DisruptRadar — Monthly Projection · Full Sensitivity — Pro Price and Fixed Costs
A30: Demand Thresholds | B30: DisruptRadar — Monthly Projection · Demand Thresholds — Price Indifference and Break-Even
A31: Demand Loss Annual Calculation | B31: DisruptRadar — Monthly Projection · Demand Loss Test — Annual Calculation
A32: Model inputs | B32: Model inputs

Sheet Excel Simulator
A1: DisruptRadar — Demand Loss, Price and Cash
A2: Local Excel test. Does not change the Model or the approved scenarios.
A5: Monthly Pro Price (EUR) | B5: ='Base Projection Controls'!B7 -> 99
A6: Demand Loss | B6: ='Demand Loss Annual Calculation'!B5 -> 0
A7: Monthly Fixed Costs (EUR) | B7: ='Base Projection Controls'!B5/12 -> 500
A8: Delivery Cost per Customer-Month (EUR) | B8: ='Demand Thresholds'!B8 -> 30
A9: Opening Cash (EUR) | B9: ='Base Projection Controls'!B10 -> 20000
A11: Simulated Customer-Months | B11: =SUM(B27:M27) -> 304
A12: Simulated Annual EBITDA (EUR) | B12: =SUM(B31:M31) -> 14976
A13: Minimum Monthly Cash (EUR) | B13: =MIN(B32:M32) -> 19345
A14: Closing Cash (EUR) | B14: =M32 -> 34976
A15: EBITDA Difference vs Approved Base Case (EUR) | B15: =B12-'Base Annual Reconciliation'!B10 -> 0
A17: Customer-Months to Match Base EBITDA | B17: =IF(B5-B8>0,('Base Annual Reconciliation'!B10+B7*12)/(B5-B8),"No finite threshold") -> 304
A18: Maximum Allowable Demand Loss | B18: =IF(ISNUMBER(B17),1-B17/'Base Annual Reconciliation'!B5,"No finite threshold") -> 0
A19: Customer-Months for Absolute Break-Even | B19: =IF(B5-B8>0,B7*12/(B5-B8),"No finite threshold") -> 86.956522
A20: Minimum Whole Customer-Months for Break-Even | B20: =IF(ISNUMBER(B19),CEILING(B19,1),"No finite threshold") -> 87
A22: Assumption: proportional demand loss in every month; avoidable delivery costs follow customer volumes; fixed costs remain unchanged.
A23: Excludes taxes, capital expenditure, overage charges and collection delays. Fractional quantities represent expected demand.
A25: Metric | B25: ='Base Monthly Projection'!B4 -> 2027-01 | C25: ='Base Monthly Projection'!C4 -> 2027-02 | D25: ='Base Monthly Projection'!D4 -> 2027-03 | E25: ='Base Monthly Projection'!E4 -> 2027-04 | F25: ='Base Monthly Projection'!F4 -> 2027-05 | G25: ='Base Monthly Projection'!G4 -> 2027-06 | H25: ='Base Monthly Projection'!H4 -> 2027-07 | I25: ='Base Monthly Projection'!I4 -> 2027-08 | ... M25: ='Base Monthly Projection'!M4 -> 2027-12 | O25: Year / Closing Balance
A26: Base Month-End Customers | B26: ='Base Monthly Projection'!B5 -> 1 | C26: ='Base Monthly Projection'!C5 -> 4 | D26: ='Base Monthly Projection'!D5 -> 9 | E26: ='Base Monthly Projection'!E5 -> 14 | F26: ='Base Monthly Projection'!F5 -> 20 | G26: ='Base Monthly Projection'!G5 -> 26 | H26: ='Base Monthly Projection'!H5 -> 32 | I26: ='Base Monthly Projection'!I5 -> 38 | ... M26: ='Base Monthly Projection'!M5 -> 40 | O26: =SUM(B26:M26) -> 304
A27: Simulated Month-End Customers | B27: =B26*(1-$B$6) -> 1 | C27: =C26*(1-$B$6) -> 4 | D27: =D26*(1-$B$6) -> 9 | E27: =E26*(1-$B$6) -> 14 | F27: =F26*(1-$B$6) -> 20 | G27: =G26*(1-$B$6) -> 26 | H27: =H26*(1-$B$6) -> 32 | I27: =I26*(1-$B$6) -> 38 | ... M27: =M26*(1-$B$6) -> 40 | O27: =SUM(B27:M27) -> 304
A28: Simulated Revenue (EUR) | B28: =B27*$B$5 -> 99 | C28: =C27*$B$5 -> 396 | D28: =D27*$B$5 -> 891 | E28: =E27*$B$5 -> 1386 | F28: =F27*$B$5 -> 1980 | G28: =G27*$B$5 -> 2574 | H28: =H27*$B$5 -> 3168 | I28: =I27*$B$5 -> 3762 | ... M28: =M27*$B$5 -> 3960 | O28: =SUM(B28:M28) -> 30096
A29: Simulated Delivery Costs (EUR) | B29: =B27*$B$8 -> 30 | C29: =C27*$B$8 -> 120 | D29: =D27*$B$8 -> 270 | E29: =E27*$B$8 -> 420 | F29: =F27*$B$8 -> 600 | G29: =G27*$B$8 -> 780 | H29: =H27*$B$8 -> 960 | I29: =I27*$B$8 -> 1140 | ... M29: =M27*$B$8 -> 1200 | O29: =SUM(B29:M29) -> 9120
A30: Simulated Fixed Costs (EUR) | B30: =$B$7 -> 500 | C30: =$B$7 -> 500 | D30: =$B$7 -> 500 | E30: =$B$7 -> 500 | F30: =$B$7 -> 500 | G30: =$B$7 -> 500 | H30: =$B$7 -> 500 | I30: =$B$7 -> 500 | ... M30: =$B$7 -> 500 | O30: =SUM(B30:M30) -> 6000
A31: Simulated EBITDA (EUR) | B31: =B28-B29-B30 -> -431 | C31: =C28-C29-C30 -> -224 | D31: =D28-D29-D30 -> 121 | E31: =E28-E29-E30 -> 466 | F31: =F28-F29-F30 -> 880 | G31: =G28-G29-G30 -> 1294 | H31: =H28-H29-H30 -> 1708 | I31: =I28-I29-I30 -> 2122 | ... M31: =M28-M29-M30 -> 2260 | O31: =SUM(B31:M31) -> 14976
A32: Simulated Closing Cash (EUR) | B32: =$B$9+B31 -> 19569 | C32: =B32+C31 -> 19345 | D32: =C32+D31 -> 19466 | E32: =D32+E31 -> 19932 | F32: =E32+F31 -> 20812 | G32: =F32+G31 -> 22106 | H32: =G32+H31 -> 23814 | I32: =H32+I31 -> 25936 | J32: =I32+J31 -> 28196 | ... M32: =L32+M31 -> 34976 | O32: =M32 -> 34976
A33: Approved Base Cash (EUR) | B33: ='Base Monthly Projection'!B12 -> 19569 | C33: ='Base Monthly Projection'!C12 -> 19345 | D33: ='Base Monthly Projection'!D12 -> 19466 | E33: ='Base Monthly Projection'!E12 -> 19932 | F33: ='Base Monthly Projection'!F12 -> 20812 | G33: ='Base Monthly Projection'!G12 -> 22106 | H33: ='Base Monthly Projection'!H12 -> 23814 | I33: ='Base Monthly Projection'!I12 -> 25936 | ... M33: ='Base Monthly Projection'!M12 -> 34976 | O33: =M33 -> 34976

Sheet Scenario Matrix
A1: DisruptRadar Business Plan · DisruptRadar Scenario Matrix
A2: Financial model (2 pages) · Base
A4: Variable / dimension | B4: Value | C4: Value > Pessimistic | D4: Value > Optimistic
A5: Subscribers (Year-End) | B5: =40 -> 40 | C5: =12 -> 12 | D5: =100 -> 100
A6: Annual Revenue (EUR) | B6: =30096 -> 30096 | C6: =8000 -> 8000 | D6: =80000 -> 80000
A7: Annual Costs (EUR) | B7: =15120 -> 15120 | C7: =6000 -> 6000 | D7: =24000 -> 24000
A8: EBITDA (EUR) | B8: ='Scenario Matrix'!B6-'Scenario Matrix'!B7 -> 14976 | C8: ='Scenario Matrix'!C6-'Scenario Matrix'!C7 -> 2000 | D8: ='Scenario Matrix'!D6-'Scenario Matrix'!D7 -> 56000
A9: Gross Margin | B9: =0.8 -> 0.8 | C9: =0.75 -> 0.75 | D9: =0.85 -> 0.85
A10: Cash Coverage with Zero Revenue (Months) | B10: =IFERROR('Year 1 Assumptions'!B7/'Scenario Matrix'!B7*12,"") -> 15.873016 | C10: =IFERROR('Model inputs'!Z13/'Scenario Matrix'!C7*12,"") -> 40 | D10: =IFERROR('Model inputs'!Z14/'Scenario Matrix'!D7*12,"") -> 10

Sheet Year 1 Assumptions
A1: DisruptRadar Business Plan · DisruptRadar Assumptions — Year 1
A2: Financial model (2 pages) · Base
A4: Variable / dimension | B4: Value
A5: Monthly Pro Price (EUR) | B5: =99 -> 99
A6: Proposed Monthly Enterprise Price (EUR) | B6: =499 -> 499
A7: Opening Cash (EUR) | B7: =20000 -> 20000
A8: Monthly Fixed Costs (EUR) | B8: =500 -> 500
A9: Minimum Addressable Market (Accounts) | B9: =500 -> 500
A10: Maximum Addressable Market (Accounts) | B10: =1000 -> 1000
A11: Variable Cost per Domain per Month — Estimate (EUR) | B11: =3 -> 3
A12: Pro Margin after Variable Costs — One Domain per Subscriber | B12: =IFERROR(1-'Year 1 Assumptions'!B11/'Year 1 Assumptions'!B5,"") -> 0.96969697
A13: Domains Included in the Pro Plan | B13: =10 -> 10
A14: Average Domains per Pro Customer — Assumption | B14: =10 -> 10
A15: Monthly Delivery Cost per Pro Customer (EUR) | B15: ='Year 1 Assumptions'!B14*'Year 1 Assumptions'!B11 -> 30
A16: Pro Contribution Margin — Average Usage | B16: =IFERROR(('Year 1 Assumptions'!B5-'Year 1 Assumptions'!B15)/'Year 1 Assumptions'!B5,"") -> 0.6969697

Sheet Usage-Based Delivery Costs
A1: DisruptRadar Business Plan · Usage-Based Delivery Costs — Pro Reference
A2: Financial model (2 pages) · Base
A4: Variable / dimension | B4: Value | C4: Value > Pessimistic | D4: Value > Optimistic
A5: Subscribers (Year-End) | B5: =40 -> 40 | C5: ='Scenario Matrix'!C5 -> 12 | D5: ='Scenario Matrix'!D5 -> 100
A6: Domains Monitored at Year-End — Pro Reference | B6: ='Year 1 Assumptions'!B14*'Usage-Based Delivery Costs'!B5 -> 400 | C6: ='Model inputs'!Z38*'Usage-Based Delivery Costs'!C5 -> 120 | D6: ='Model inputs'!Z39*'Usage-Based Delivery Costs'!D5 -> 1000
A7: Monthly Delivery Costs at Year-End — Pro Reference (EUR) | B7: ='Year 1 Assumptions'!B14*'Year 1 Assumptions'!B11*'Usage-Based Delivery Costs'!B5 -> 1200 | C7: ='Model inputs'!Z38*'Model inputs'!Z28*'Usage-Based Delivery Costs'!C5 -> 360 | D7: ='Model inputs'!Z39*'Model inputs'!Z29*'Usage-Based Delivery Costs'!D5 -> 3000

Sheet Base Projection Controls
A1: DisruptRadar — Monthly Projection · Base Projection Controls
A2: Financial model (2 pages) · Base
A4: Variable / dimension | B4: Value
A5: Annual Fixed Costs for the Base Projection (EUR) | B5: =6000 -> 6000
A6: Base Projection Start Date | B6: =DATE(2027,1,1) -> 46388
A7: Monthly Pro Price (EUR) | B7: =99 -> 99
A8: Average Domains per Pro Customer — Assumption | B8: =10 -> 10
A9: Variable Cost per Domain per Month — Estimate (EUR) | B9: =3 -> 3
A10: Opening Cash (EUR) | B10: =20000 -> 20000

Sheet Base Monthly Projection
A1: DisruptRadar — Monthly Projection · Base Monthly Projection — Customers, Earnings and Cash
A2: Financial model (2 pages) · Base
A4: Variable / dimension | B4: 2027-01 | C4: 2027-02 | D4: 2027-03 | E4: 2027-04 | F4: 2027-05 | G4: 2027-06 | H4: 2027-07 | I4: 2027-08 | J4: 2027-09 | K4: 2027-10 | L4: 2027-11 | M4: 2027-12
A5: Month-End Customers — Base Projection | B5: =1 -> 1 | C5: =4 -> 4 | D5: =9 -> 9 | E5: =14 -> 14 | F5: =20 -> 20 | G5: =26 -> 26 | H5: =32 -> 32 | I5: =38 -> 38 | J5: =40 -> 40 | K5: =40 -> 40 | L5: =40 -> 40 | M5: =40 -> 40
A6: Monthly Revenue — Base Projection (EUR) | B6: ='Base Monthly Projection'!B5*'Year 1 Assumptions'!B5 -> 99 | C6: ='Base Monthly Projection'!C5*'Year 1 Assumptions'!B5 -> 396 | D6: ='Base Monthly Projection'!D5*'Year 1 Assumptions'!B5 -> 891 | E6: ='Base Monthly Projection'!E5*'Year 1 Assumptions'!B5 -> 1386 | F6: ='Base Monthly Projection'!F5*'Year 1 Assumptions'!B5 -> 1980 | G6: ='Base Monthly Projection'!G5*'Year 1 Assumptions'!B5 -> 2574 | H6: ='Base Monthly Projection'!H5*'Year 1 Assumptions'!B5 -> 3168 | I6: ='Base Monthly Projection'!I5*'Year 1 Assumptions'!B5 -> 3762 | J6: ='Base Monthly Projection'!J5*'Year 1 Assumptions'!B5 -> 3960 | K6: ='Base Monthly Projection'!K5*'Year 1 Assumptions'!B5 -> 3960 | L6: ='Base Monthly Projection'!L5*'Year 1 Assumptions'!B5 -> 3960 | M6: ='Base Monthly Projection'!M5*'Year 1 Assumptions'!B5 -> 3960
A7: Monthly Delivery Costs — Base Projection (EUR) | B7: ='Base Monthly Projection'!B5*'Year 1 Assumptions'!B14*'Year 1 Assumptions'!B11 -> 30 | C7: ='Base Monthly Projection'!C5*'Year 1 Assumptions'!B14*'Year 1 Assumptions'!B11 -> 120 | D7: ='Base Monthly Projection'!D5*'Year 1 Assumptions'!B14*'Year 1 Assumptions'!B11 -> 270 | E7: ='Base Monthly Projection'!E5*'Year 1 Assumptions'!B14*'Year 1 Assumptions'!B11 -> 420 | F7: ='Base Monthly Projection'!F5*'Year 1 Assumptions'!B14*'Year 1 Assumptions'!B11 -> 600 | G7: ='Base Monthly Projection'!G5*'Year 1 Assumptions'!B14*'Year 1 Assumptions'!B11 -> 780 | H7: ='Base Monthly Projection'!H5*'Year 1 Assumptions'!B14*'Year 1 Assumptions'!B11 -> 960 | I7: ='Base Monthly Projection'!I5*'Year 1 Assumptions'!B14*'Year 1 Assumptions'!B11 -> 1140 | J7: ='Base Monthly Projection'!J5*'Year 1 Assumptions'!B14*'Year 1 Assumptions'!B11 -> 1200 | K7: ='Base Monthly Projection'!K5*'Year 1 Assumptions'!B14*'Year 1 Assumptions'!B11 -> 1200 | L7: ='Base Monthly Projection'!L5*'Year 1 Assumptions'!B14*'Year 1 Assumptions'!B11 -> 1200 | M7: ='Base Monthly Projection'!M5*'Year 1 Assumptions'!B14*'Year 1 Assumptions'!B11 -> 1200
A8: Monthly Fixed Costs — Base Projection (EUR) | B8: ='Base Projection Controls'!B5/12 -> 500 | C8: ='Base Projection Controls'!B5/12 -> 500 | D8: ='Base Projection Controls'!B5/12 -> 500 | E8: ='Base Projection Controls'!B5/12 -> 500 | F8: ='Base Projection Controls'!B5/12 -> 500 | G8: ='Base Projection Controls'!B5/12 -> 500 | H8: ='Base Projection Controls'!B5/12 -> 500 | I8: ='Base Projection Controls'!B5/12 -> 500 | J8: ='Base Projection Controls'!B5/12 -> 500 | K8: ='Base Projection Controls'!B5/12 -> 500 | L8: ='Base Projection Controls'!B5/12 -> 500 | M8: ='Base Projection Controls'!B5/12 -> 500
A9: Total Monthly Costs — Base Projection (EUR) | B9: ='Base Monthly Projection'!B7+'Base Monthly Projection'!B8 -> 530 | C9: ='Base Monthly Projection'!C7+'Base Monthly Projection'!C8 -> 620 | D9: ='Base Monthly Projection'!D7+'Base Monthly Projection'!D8 -> 770 | E9: ='Base Monthly Projection'!E7+'Base Monthly Projection'!E8 -> 920 | F9: ='Base Monthly Projection'!F7+'Base Monthly Projection'!F8 -> 1100 | G9: ='Base Monthly Projection'!G7+'Base Monthly Projection'!G8 -> 1280 | H9: ='Base Monthly Projection'!H7+'Base Monthly Projection'!H8 -> 1460 | I9: ='Base Monthly Projection'!I7+'Base Monthly Projection'!I8 -> 1640 | ... M9: ='Base Monthly Projection'!M7+'Base Monthly Projection'!M8 -> 1700
A10: Monthly EBITDA — Base Projection (EUR) | B10: ='Base Monthly Projection'!B6-'Base Monthly Projection'!B9 -> -431 | C10: ='Base Monthly Projection'!C6-'Base Monthly Projection'!C9 -> -224 | D10: ='Base Monthly Projection'!D6-'Base Monthly Projection'!D9 -> 121 | E10: ='Base Monthly Projection'!E6-'Base Monthly Projection'!E9 -> 466 | F10: ='Base Monthly Projection'!F6-'Base Monthly Projection'!F9 -> 880 | G10: ='Base Monthly Projection'!G6-'Base Monthly Projection'!G9 -> 1294 | H10: ='Base Monthly Projection'!H6-'Base Monthly Projection'!H9 -> 1708 | I10: ='Base Monthly Projection'!I6-'Base Monthly Projection'!I9 -> 2122 | ... M10: ='Base Monthly Projection'!M6-'Base Monthly Projection'!M9 -> 2260
A11: Opening Monthly Cash — Base Projection (EUR) | B11: =IF(IF(IF(ISERROR(DATE(2027,1,1)=DATE(YEAR('Base Projection Controls'!B6),MONTH('Base Projection Controls'!B6),1)),DATE(2027,1,1)=DATE(YEAR('Base Projection Controls'!B6),MONTH('Base Projection Controls'!B6),1),IF(DATE(YEAR('Base Projection Controls'!B6),MONTH('Base Projection Controls'!B6),1)="","",DATE(2027,1,1)=DATE(YEAR('Base Projection Controls'!B6),MONTH('Base Projection Controls'!B6),1)))="",FALSE(),IF(ISERROR(DATE(2027,1,1)=DATE(YEAR('Base Projection Controls'!B6),MONTH('Base Projection Controls'!B6),1)),DATE(2027,1,1)=DATE(YEAR('Base Projection Controls'!B6),MONTH('Base Projection Controls'!B6),1),IF(DATE(YEAR('Base Projection Controls'!B6),MONTH('Base Projection Controls'!B6),1)="","",DATE(2027,1,1)=DATE(YEAR('Base Projection Controls'!B6),MONTH('Base Projection Controls'!B6),1)))),IF('Year 1 Assumptions'!B7="","",'Year 1 Assumptions'!B7),IF('Model inputs'!B6="","",'Model inputs'!B6)) -> 20000 | C11: =IF(IF(IF(ISERROR(DATE(2027,2,1)=DATE(YEAR('Base Projection Controls'!B6),MONTH('Base Projection Controls'!B6),1)),DATE(2027,2,1)=DATE(YEAR('Base Projection Controls'!B6),MONTH('Base Projection Controls'!B6),1),IF(DATE(YEAR('Base Projection Controls'!B6),MONTH('Base Projection Controls'!B6),1)="","",DATE(2027,2,1)=DATE(YEAR('Base Projection Controls'!B6),MONTH('Base Projection Controls'!B6),1)))="",FALSE(),IF(ISERROR(DATE(2027,2,1)=DATE(YEAR('Base Projection Controls'!B6),MONTH('Base Projection Controls'!B6),1)),DATE(2027,2,1)=DATE(YEAR('Base Projection Controls'!B6),MONTH('Base Projection Controls'!B6),1),IF(DATE(YEAR('Base Projection Controls'!B6),MONTH('Base Projection Controls'!B6),1)="","",DATE(2027,2,1)=DATE(YEAR('Base Projection Controls'!B6),MONTH('Base Projection Controls'!B6),1)))),IF('Year 1 Assumptions'!B7="","",'Year 1 Assumptions'!B7),IF('Base Monthly Projection'!B12="","",'Base Monthly Projection'!B12)) -> 19569 | D11: =IF(IF(IF(ISERROR(DATE(2027,3,1)=DATE(YEAR('Base Projection Controls'!B6),MONTH('Base Projection Controls'!B6),1)),DATE(2027,3,1)=DATE(YEAR('Base Projection Controls'!B6),MONTH('Base Projection Controls'!B6),1),IF(DATE(YEAR('Base Projection Controls'!B6),MONTH('Base Projection Controls'!B6),1)="","",DATE(2027,3,1)=DATE(YEAR('Base Projection Controls'!B6),MONTH('Base Projection Controls'!B6),1)))="",FALSE(),IF(ISERROR(DATE(2027,3,1)=DATE(YEAR('Base Projection Controls'!B6),MONTH('Base Projection Controls'!B6),1)),DATE(2027,3,1)=DATE(YEAR('Base Projection Controls'!B6),MONTH('Base Projection Controls'!B6),1),IF(DATE(YEAR('Base Projection Controls'!B6),MONTH('Base Projection Controls'!B6),1)="","",DATE(2027,3,1)=DATE(YEAR('Base Projection Controls'!B6),MONTH('Base Projection Controls'!B6),1)))),IF('Year 1 Assumptions'!B7="","",'Year 1 Assumptions'!B7),IF('Base Monthly Projection'!C12="","",'Base Monthly Projection'!C12)) -> 19345 | E11: =IF(IF(IF(ISERROR(DATE(2027,4,1)=DATE(YEAR('Base Projection Controls'!B6),MONTH('Base Projection Controls'!B6),1)),DATE(2027,4,1)=DATE(YEAR('Base Projection Controls'!B6),MONTH('Base Projection Controls'!B6),1),IF(DATE(YEAR('Base Projection Controls'!B6),MONTH('Base Projection Controls'!B6),1)="","",DATE(2027,4,1)=DATE(YEAR('Base Projection Controls'!B6),MONTH('Base Projection Controls'!B6),1)))="",FALSE(),IF(ISERROR(DATE(2027,4,1)=DATE(YEAR('Base Projection Controls'!B6),MONTH('Base Projection Controls'!B6),1)),DATE(2027,4,1)=DATE(YEAR('Base Projection Controls'!B6),MONTH('Base Projection Controls'!B6),1),IF(DATE(YEAR('Base Projection Controls'!B6),MONTH('Base Projection Controls'!B6),1)="","",DATE(2027,4,1)=DATE(YEAR('Base Projection Controls'!B6),MONTH('Base Projection Controls'!B6),1)))),IF('Year 1 Assumptions'!B7="","",'Year 1 Assumptions'!B7),IF('Base Monthly Projection'!D12="","",'Base Monthly Projection'!D12)) -> 19466 | F11: =IF(IF(IF(ISERROR(DATE(2027,5,1)=DATE(YEAR('Base Projection Controls'!B6),MONTH('Base Projection Controls'!B6),1)),DATE(2027,5,1)=DATE(YEAR('Base Projection Controls'!B6),MONTH('Base Projection Controls'!B6),1),IF(DATE(YEAR('Base Projection Controls'!B6),MONTH('Base Projection Controls'!B6),1)="","",DATE(2027,5,1)=DATE(YEAR('Base Projection Controls'!B6),MONTH('Base Projection Controls'!B6),1)))="",FALSE(),IF(ISERROR(DATE(2027,5,1)=DATE(YEAR('Base Projection Controls'!B6),MONTH('Base Projection Controls'!B6),1)),DATE(2027,5,1)=DATE(YEAR('Base Projection Controls'!B6),MONTH('Base Projection Controls'!B6),1),IF(DATE(YEAR('Base Projection Controls'!B6),MONTH('Base Projection Controls'!B6),1)="","",DATE(2027,5,1)=DATE(YEAR('Base Projection Controls'!B6),MONTH('Base Projection Controls'!B6),1)))),IF('Year 1 Assumptions'!B7="","",'Year 1 Assumptions'!B7),IF('Base Monthly Projection'!E12="","",'Base Monthly Projection'!E12)) -> 19932 | G11: =IF(IF(IF(ISERROR(DATE(2027,6,1)=DATE(YEAR('Base Projection Controls'!B6),MONTH('Base Projection Controls'!B6),1)),DATE(2027,6,1)=DATE(YEAR('Base Projection Controls'!B6),MONTH('Base Projection Controls'!B6),1),IF(DATE(YEAR('Base Projection Controls'!B6),MONTH('Base Projection Controls'!B6),1)="","",DATE(2027,6,1)=DATE(YEAR('Base Projection Controls'!B6),MONTH('Base Projection Controls'!B6),1)))="",FALSE(),IF(ISERROR(DATE(2027,6,1)=DATE(YEAR('Base Projection Controls'!B6),MONTH('Base Projection Controls'!B6),1)),DATE(2027,6,1)=DATE(YEAR('Base Projection Controls'!B6),MONTH('Base Projection Controls'!B6),1),IF(DATE(YEAR('Base Projection Controls'!B6),MONTH('Base Projection Controls'!B6),1)="","",DATE(2027,6,1)=DATE(YEAR('Base Projection Controls'!B6),MONTH('Base Projection Controls'!B6),1)))),IF('Year 1 Assumptions'!B7="","",'Year 1 Assumptions'!B7),IF('Base Monthly Projection'!F12="","",'Base Monthly Projection'!F12)) -> 20812 | H11: =IF(IF(IF(ISERROR(DATE(2027,7,1)=DATE(YEAR('Base Projection Controls'!B6),MONTH('Base Projection Controls'!B6),1)),DATE(2027,7,1)=DATE(YEAR('Base Projection Controls'!B6),MONTH('Base Projection Controls'!B6),1),IF(DATE(YEAR('Base Projection Controls'!B6),MONTH('Base Projection Controls'!B6),1)="","",DATE(2027,7,1)=DATE(YEAR('Base Projection Controls'!B6),MONTH('Base Projection Controls'!B6),1)))="",FALSE(),IF(ISERROR(DATE(2027,7,1)=DATE(YEAR('Base Projection Controls'!B6),MONTH('Base Projection Controls'!B6),1)),DATE(2027,7,1)=DATE(YEAR('Base Projection Controls'!B6),MONTH('Base Projection Controls'!B6),1),IF(DATE(YEAR('Base Projection Controls'!B6),MONTH('Base Projection Controls'!B6),1)="","",DATE(2027,7,1)=DATE(YEAR('Base Projection Controls'!B6),MONTH('Base Projection Controls'!B6),1)))),IF('Year 1 Assumptions'!B7="","",'Year 1 Assumptions'!B7),IF('Base Monthly Projection'!G12="","",'Base Monthly Projection'!G12)) -> 22106 | I11: =IF(IF(IF(ISERROR(DATE(2027,8,1)=DATE(YEAR('Base Projection Controls'!B6),MONTH('Base Projection Controls'!B6),1)),DATE(2027,8,1)=DATE(YEAR('Base Projection Controls'!B6),MONTH('Base Projection Controls'!B6),1),IF(DATE(YEAR('Base Projection Controls'!B6),MONTH('Base Projection Controls'!B6),1)="","",DATE(2027,8,1)=DATE(YEAR('Base Projection Controls'!B6),MONTH('Base Projection Controls'!B6),1)))="",FALSE(),IF(ISERROR(DATE(2027,8,1)=DATE(YEAR('Base Projection Controls'!B6),MONTH('Base Projection Controls'!B6),1)),DATE(2027,8,1)=DATE(YEAR('Base Projection Controls'!B6),MONTH('Base Projection Controls'!B6),1),IF(DATE(YEAR('Base Projection Controls'!B6),MONTH('Base Projection Controls'!B6),1)="","",DATE(2027,8,1)=DATE(YEAR('Base Projection Controls'!B6),MONTH('Base Projection Controls'!B6),1)))),IF('Year 1 Assumptions'!B7="","",'Year 1 Assumptions'!B7),IF('Base Monthly Projection'!H12="","",'Base Monthly Projection'!H12)) -> 23814 | J11: =IF(IF(IF(ISERROR(DATE(2027,9,1)=DATE(YEAR('Base Projection Controls'!B6),MONTH('Base Projection Controls'!B6),1)),DATE(2027,9,1)=DATE(YEAR('Base Projection Controls'!B6),MONTH('Base Projection Controls'!B6),1),IF(DATE(YEAR('Base Projection Controls'!B6),MONTH('Base Projection Controls'!B6),1)="","",DATE(2027,9,1)=DATE(YEAR('Base Projection Controls'!B6),MONTH('Base Projection Controls'!B6),1)))="",FALSE(),IF(ISERROR(DATE(2027,9,1)=DATE(YEAR('Base Projection Controls'!B6),MONTH('Base Projection Controls'!B6),1)),DATE(2027,9,1)=DATE(YEAR('Base Projection Controls'!B6),MONTH('Base Projection Controls'!B6),1),IF(DATE(YEAR('Base Projection Controls'!B6),MONTH('Base Projection Controls'!B6),1)="","",DATE(2027,9,1)=DATE(YEAR('Base Projection Controls'!B6),MONTH('Base Projection Controls'!B6),1)))),IF('Year 1 Assumptions'!B7="","",'Year 1 Assumptions'!B7),IF('Base Monthly Projection'!I12="","",'Base Monthly Projection'!I12)) -> 25936 | K11: =IF(IF(IF(ISERROR(DATE(2027,10,1)=DATE(YEAR('Base Projection Controls'!B6),MONTH('Base Projection Controls'!B6),1)),DATE(2027,10,1)=DATE(YEAR('Base Projection Controls'!B6),MONTH('Base Projection Controls'!B6),1),IF(DATE(YEAR('Base Projection Controls'!B6),MONTH('Base Projection Controls'!B6),1)="","",DATE(2027,10,1)=DATE(YEAR('Base Projection Controls'!B6),MONTH('Base Projection Controls'!B6),1)))="",FALSE(),IF(ISERROR(DATE(2027,10,1)=DATE(YEAR('Base Projection Controls'!B6),MONTH('Base Projection Controls'!B6),1)),DATE(2027,10,1)=DATE(YEAR('Base Projection Controls'!B6),MONTH('Base Projection Controls'!B6),1),IF(DATE(YEAR('Base Projection Controls'!B6),MONTH('Base Projection Controls'!B6),1)="","",DATE(2027,10,1)=DATE(YEAR('Base Projection Controls'!B6),MONTH('Base Projection Controls'!B6),1)))),IF('Year 1 Assumptions'!B7="","",'Year 1 Assumptions'!B7),IF('Base Monthly Projection'!J12="","",'Base Monthly Projection'!J12)) -> 28196 | L11: =IF(IF(IF(ISERROR(DATE(2027,11,1)=DATE(YEAR('Base Projection Controls'!B6),MONTH('Base Projection Controls'!B6),1)),DATE(2027,11,1)=DATE(YEAR('Base Projection Controls'!B6),MONTH('Base Projection Controls'!B6),1),IF(DATE(YEAR('Base Projection Controls'!B6),MONTH('Base Projection Controls'!B6),1)="","",DATE(2027,11,1)=DATE(YEAR('Base Projection Controls'!B6),MONTH('Base Projection Controls'!B6),1)))="",FALSE(),IF(ISERROR(DATE(2027,11,1)=DATE(YEAR('Base Projection Controls'!B6),MONTH('Base Projection Controls'!B6),1)),DATE(2027,11,1)=DATE(YEAR('Base Projection Controls'!B6),MONTH('Base Projection Controls'!B6),1),IF(DATE(YEAR('Base Projection Controls'!B6),MONTH('Base Projection Controls'!B6),1)="","",DATE(2027,11,1)=DATE(YEAR('Base Projection Controls'!B6),MONTH('Base Projection Controls'!B6),1)))),IF('Year 1 Assumptions'!B7="","",'Year 1 Assumptions'!B7),IF('Base Monthly Projection'!K12="","",'Base Monthly Projection'!K12)) -> 30456 | M11: =IF(IF(IF(ISERROR(DATE(2027,12,1)=DATE(YEAR('Base Projection Controls'!B6),MONTH('Base Projection Controls'!B6),1)),DATE(2027,12,1)=DATE(YEAR('Base Projection Controls'!B6),MONTH('Base Projection Controls'!B6),1),IF(DATE(YEAR('Base Projection Controls'!B6),MONTH('Base Projection Controls'!B6),1)="","",DATE(2027,12,1)=DATE(YEAR('Base Projection Controls'!B6),MONTH('Base Projection Controls'!B6),1)))="",FALSE(),IF(ISERROR(DATE(2027,12,1)=DATE(YEAR('Base Projection Controls'!B6),MONTH('Base Projection Controls'!B6),1)),DATE(2027,12,1)=DATE(YEAR('Base Projection Controls'!B6),MONTH('Base Projection Controls'!B6),1),IF(DATE(YEAR('Base Projection Controls'!B6),MONTH('Base Projection Controls'!B6),1)="","",DATE(2027,12,1)=DATE(YEAR('Base Projection Controls'!B6),MONTH('Base Projection Controls'!B6),1)))),IF('Year 1 Assumptions'!B7="","",'Year 1 Assumptions'!B7),IF('Base Monthly Projection'!L12="","",'Base Monthly Projection'!L12)) -> 32716
A12: Closing Cash — Base Projection (EUR) | B12: ='Base Monthly Projection'!B11+'Base Monthly Projection'!B10 -> 19569 | C12: ='Base Monthly Projection'!C11+'Base Monthly Projection'!C10 -> 19345 | D12: ='Base Monthly Projection'!D11+'Base Monthly Projection'!D10 -> 19466 | E12: ='Base Monthly Projection'!E11+'Base Monthly Projection'!E10 -> 19932 | F12: ='Base Monthly Projection'!F11+'Base Monthly Projection'!F10 -> 20812 | G12: ='Base Monthly Projection'!G11+'Base Monthly Projection'!G10 -> 22106 | H12: ='Base Monthly Projection'!H11+'Base Monthly Projection'!H10 -> 23814 | I12: ='Base Monthly Projection'!I11+'Base Monthly Projection'!I10 -> 25936 | ... M12: ='Base Monthly Projection'!M11+'Base Monthly Projection'!M10 -> 34976
A13: Cumulative Cash Movement — Base Projection (EUR) | B13: =IF(IF(IF(IF(ISERROR(DATE(2027,1,1)=DATE(YEAR('Base Projection Controls'!B6),MONTH('Base Projection Controls'!B6),1)),DATE(2027,1,1)=DATE(YEAR('Base Projection Controls'!B6),MONTH('Base Projection Controls'!B6),1),IF(DATE(YEAR('Base Projection Controls'!B6),MONTH('Base Projection Controls'!B6),1)="","",DATE(2027,1,1)=DATE(YEAR('Base Projection Controls'!B6),MONTH('Base Projection Controls'!B6),1)))="",FALSE(),IF(ISERROR(DATE(2027,1,1)=DATE(YEAR('Base Projection Controls'!B6),MONTH('Base Projection Controls'!B6),1)),DATE(2027,1,1)=DATE(YEAR('Base Projection Controls'!B6),MONTH('Base Projection Controls'!B6),1),IF(DATE(YEAR('Base Projection Controls'!B6),MONTH('Base Projection Controls'!B6),1)="","",DATE(2027,1,1)=DATE(YEAR('Base Projection Controls'!B6),MONTH('Base Projection Controls'!B6),1)))),0,IF('Model inputs'!B64="","",'Model inputs'!B64))="",0,IF(IF(IF(ISERROR(DATE(2027,1,1)=DATE(YEAR('Base Projection Controls'!B6),MONTH('Base Projection Controls'!B6),1)),DATE(2027,1,1)=DATE(YEAR('Base Projection Controls'!B6),MONTH('Base Projection Controls'!B6),1),IF(DATE(YEAR('Base Projection Controls'!B6),MONTH('Base Projection Controls'!B6),1)="","",DATE(2027,1,1)=DATE(YEAR('Base Projection Controls'!B6),MONTH('Base Projection Controls'!B6),1)))="",FALSE(),IF(ISERROR(DATE(2027,1,1)=DATE(YEAR('Base Projection Controls'!B6),MONTH('Base Projection Controls'!B6),1)),DATE(2027,1,1)=DATE(YEAR('Base Projection Controls'!B6),MONTH('Base Projection Controls'!B6),1),IF(DATE(YEAR('Base Projection Controls'!B6),MONTH('Base Projection Controls'!B6),1)="","",DATE(2027,1,1)=DATE(YEAR('Base Projection Controls'!B6),MONTH('Base Projection Controls'!B6),1)))),0,IF('Model inputs'!B64="","",'Model inputs'!B64)))+'Base Monthly Projection'!B10 -> -431 | C13: =IF(IF(IF(IF(ISERROR(DATE(2027,2,1)=DATE(YEAR('Base Projection Controls'!B6),MONTH('Base Projection Controls'!B6),1)),DATE(2027,2,1)=DATE(YEAR('Base Projection Controls'!B6),MONTH('Base Projection Controls'!B6),1),IF(DATE(YEAR('Base Projection Controls'!B6),MONTH('Base Projection Controls'!B6),1)="","",DATE(2027,2,1)=DATE(YEAR('Base Projection Controls'!B6),MONTH('Base Projection Controls'!B6),1)))="",FALSE(),IF(ISERROR(DATE(2027,2,1)=DATE(YEAR('Base Projection Controls'!B6),MONTH('Base Projection Controls'!B6),1)),DATE(2027,2,1)=DATE(YEAR('Base Projection Controls'!B6),MONTH('Base Projection Controls'!B6),1),IF(DATE(YEAR('Base Projection Controls'!B6),MONTH('Base Projection Controls'!B6),1)="","",DATE(2027,2,1)=DATE(YEAR('Base Projection Controls'!B6),MONTH('Base Projection Controls'!B6),1)))),0,IF('Base Monthly Projection'!B13="","",'Base Monthly Projection'!B13))="",0,IF(IF(IF(ISERROR(DATE(2027,2,1)=DATE(YEAR('Base Projection Controls'!B6),MONTH('Base Projection Controls'!B6),1)),DATE(2027,2,1)=DATE(YEAR('Base Projection Controls'!B6),MONTH('Base Projection Controls'!B6),1),IF(DATE(YEAR('Base Projection Controls'!B6),MONTH('Base Projection Controls'!B6),1)="","",DATE(2027,2,1)=DATE(YEAR('Base Projection Controls'!B6),MONTH('Base Projection Controls'!B6),1)))="",FALSE(),IF(ISERROR(DATE(2027,2,1)=DATE(YEAR('Base Projection Controls'!B6),MONTH('Base Projection Controls'!B6),1)),DATE(2027,2,1)=DATE(YEAR('Base Projection Controls'!B6),MONTH('Base Projection Controls'!B6),1),IF(DATE(YEAR('Base Projection Controls'!B6),MONTH('Base Projection Controls'!B6),1)="","",DATE(2027,2,1)=DATE(YEAR('Base Projection Controls'!B6),MONTH('Base Projection Controls'!B6),1)))),0,IF('Base Monthly Projection'!B13="","",'Base Monthly Projection'!B13)))+'Base Monthly Projection'!C10 -> -655 | D13: =IF(IF(IF(IF(ISERROR(DATE(2027,3,1)=DATE(YEAR('Base Projection Controls'!B6),MONTH('Base Projection Controls'!B6),1)),DATE(2027,3,1)=DATE(YEAR('Base Projection Controls'!B6),MONTH('Base Projection Controls'!B6),1),IF(DATE(YEAR('Base Projection Controls'!B6),MONTH('Base Projection Controls'!B6),1)="","",DATE(2027,3,1)=DATE(YEAR('Base Projection Controls'!B6),MONTH('Base Projection Controls'!B6),1)))="",FALSE(),IF(ISERROR(DATE(2027,3,1)=DATE(YEAR('Base Projection Controls'!B6),MONTH('Base Projection Controls'!B6),1)),DATE(2027,3,1)=DATE(YEAR('Base Projection Controls'!B6),MONTH('Base Projection Controls'!B6),1),IF(DATE(YEAR('Base Projection Controls'!B6),MONTH('Base Projection Controls'!B6),1)="","",DATE(2027,3,1)=DATE(YEAR('Base Projection Controls'!B6),MONTH('Base Projection Controls'!B6),1)))),0,IF('Base Monthly Projection'!C13="","",'Base Monthly Projection'!C13))="",0,IF(IF(IF(ISERROR(DATE(2027,3,1)=DATE(YEAR('Base Projection Controls'!B6),MONTH('Base Projection Controls'!B6),1)),DATE(2027,3,1)=DATE(YEAR('Base Projection Controls'!B6),MONTH('Base Projection Controls'!B6),1),IF(DATE(YEAR('Base Projection Controls'!B6),MONTH('Base Projection Controls'!B6),1)="","",DATE(2027,3,1)=DATE(YEAR('Base Projection Controls'!B6),MONTH('Base Projection Controls'!B6),1)))="",FALSE(),IF(ISERROR(DATE(2027,3,1)=DATE(YEAR('Base Projection Controls'!B6),MONTH('Base Projection Controls'!B6),1)),DATE(2027,3,1)=DATE(YEAR('Base Projection Controls'!B6),MONTH('Base Projection Controls'!B6),1),IF(DATE(YEAR('Base Projection Controls'!B6),MONTH('Base Projection Controls'!B6),1)="","",DATE(2027,3,1)=DATE(YEAR('Base Projection Controls'!B6),MONTH('Base Projection Controls'!B6),1)))),0,IF('Base Monthly Projection'!C13="","",'Base Monthly Projection'!C13)))+'Base Monthly Projection'!D10 -> -534 | E13: =IF(IF(IF(IF(ISERROR(DATE(2027,4,1)=DATE(YEAR('Base Projection Controls'!B6),MONTH('Base Projection Controls'!B6),1)),DATE(2027,4,1)=DATE(YEAR('Base Projection Controls'!B6),MONTH('Base Projection Controls'!B6),1),IF(DATE(YEAR('Base Projection Controls'!B6),MONTH('Base Projection Controls'!B6),1)="","",DATE(2027,4,1)=DATE(YEAR('Base Projection Controls'!B6),MONTH('Base Projection Controls'!B6),1)))="",FALSE(),IF(ISERROR(DATE(2027,4,1)=DATE(YEAR('Base Projection Controls'!B6),MONTH('Base Projection Controls'!B6),1)),DATE(2027,4,1)=DATE(YEAR('Base Projection Controls'!B6),MONTH('Base Projection Controls'!B6),1),IF(DATE(YEAR('Base Projection Controls'!B6),MONTH('Base Projection Controls'!B6),1)="","",DATE(2027,4,1)=DATE(YEAR('Base Projection Controls'!B6),MONTH('Base Projection Controls'!B6),1)))),0,IF('Base Monthly Projection'!D13="","",'Base Monthly Projection'!D13))="",0,IF(IF(IF(ISERROR(DATE(2027,4,1)=DATE(YEAR('Base Projection Controls'!B6),MONTH('Base Projection Controls'!B6),1)),DATE(2027,4,1)=DATE(YEAR('Base Projection Controls'!B6),MONTH('Base Projection Controls'!B6),1),IF(DATE(YEAR('Base Projection Controls'!B6),MONTH('Base Projection Controls'!B6),1)="","",DATE(2027,4,1)=DATE(YEAR('Base Projection Controls'!B6),MONTH('Base Projection Controls'!B6),1)))="",FALSE(),IF(ISERROR(DATE(2027,4,1)=DATE(YEAR('Base Projection Controls'!B6),MONTH('Base Projection Controls'!B6),1)),DATE(2027,4,1)=DATE(YEAR('Base Projection Controls'!B6),MONTH('Base Projection Controls'!B6),1),IF(DATE(YEAR('Base Projection Controls'!B6),MONTH('Base Projection Controls'!B6),1)="","",DATE(2027,4,1)=DATE(YEAR('Base Projection Controls'!B6),MONTH('Base Projection Controls'!B6),1)))),0,IF('Base Monthly Projection'!D13="","",'Base Monthly Projection'!D13)))+'Base Monthly Projection'!E10 -> -68 | F13: =IF(IF(IF(IF(ISERROR(DATE(2027,5,1)=DATE(YEAR('Base Projection Controls'!B6),MONTH('Base Projection Controls'!B6),1)),DATE(2027,5,1)=DATE(YEAR('Base Projection Controls'!B6),MONTH('Base Projection Controls'!B6),1),IF(DATE(YEAR('Base Projection Controls'!B6),MONTH('Base Projection Controls'!B6),1)="","",DATE(2027,5,1)=DATE(YEAR('Base Projection Controls'!B6),MONTH('Base Projection Controls'!B6),1)))="",FALSE(),IF(ISERROR(DATE(2027,5,1)=DATE(YEAR('Base Projection Controls'!B6),MONTH('Base Projection Controls'!B6),1)),DATE(2027,5,1)=DATE(YEAR('Base Projection Controls'!B6),MONTH('Base Projection Controls'!B6),1),IF(DATE(YEAR('Base Projection Controls'!B6),MONTH('Base Projection Controls'!B6),1)="","",DATE(2027,5,1)=DATE(YEAR('Base Projection Controls'!B6),MONTH('Base Projection Controls'!B6),1)))),0,IF('Base Monthly Projection'!E13="","",'Base Monthly Projection'!E13))="",0,IF(IF(IF(ISERROR(DATE(2027,5,1)=DATE(YEAR('Base Projection Controls'!B6),MONTH('Base Projection Controls'!B6),1)),DATE(2027,5,1)=DATE(YEAR('Base Projection Controls'!B6),MONTH('Base Projection Controls'!B6),1),IF(DATE(YEAR('Base Projection Controls'!B6),MONTH('Base Projection Controls'!B6),1)="","",DATE(2027,5,1)=DATE(YEAR('Base Projection Controls'!B6),MONTH('Base Projection Controls'!B6),1)))="",FALSE(),IF(ISERROR(DATE(2027,5,1)=DATE(YEAR('Base Projection Controls'!B6),MONTH('Base Projection Controls'!B6),1)),DATE(2027,5,1)=DATE(YEAR('Base Projection Controls'!B6),MONTH('Base Projection Controls'!B6),1),IF(DATE(YEAR('Base Projection Controls'!B6),MONTH('Base Projection Controls'!B6),1)="","",DATE(2027,5,1)=DATE(YEAR('Base Projection Controls'!B6),MONTH('Base Projection Controls'!B6),1)))),0,IF('Base Monthly Projection'!E13="","",'Base Monthly Projection'!E13)))+'Base Monthly Projection'!F10 -> 812 | G13: =IF(IF(IF(IF(ISERROR(DATE(2027,6,1)=DATE(YEAR('Base Projection Controls'!B6),MONTH('Base Projection Controls'!B6),1)),DATE(2027,6,1)=DATE(YEAR('Base Projection Controls'!B6),MONTH('Base Projection Controls'!B6),1),IF(DATE(YEAR('Base Projection Controls'!B6),MONTH('Base Projection Controls'!B6),1)="","",DATE(2027,6,1)=DATE(YEAR('Base Projection Controls'!B6),MONTH('Base Projection Controls'!B6),1)))="",FALSE(),IF(ISERROR(DATE(2027,6,1)=DATE(YEAR('Base Projection Controls'!B6),MONTH('Base Projection Controls'!B6),1)),DATE(2027,6,1)=DATE(YEAR('Base Projection Controls'!B6),MONTH('Base Projection Controls'!B6),1),IF(DATE(YEAR('Base Projection Controls'!B6),MONTH('Base Projection Controls'!B6),1)="","",DATE(2027,6,1)=DATE(YEAR('Base Projection Controls'!B6),MONTH('Base Projection Controls'!B6),1)))),0,IF('Base Monthly Projection'!F13="","",'Base Monthly Projection'!F13))="",0,IF(IF(IF(ISERROR(DATE(2027,6,1)=DATE(YEAR('Base Projection Controls'!B6),MONTH('Base Projection Controls'!B6),1)),DATE(2027,6,1)=DATE(YEAR('Base Projection Controls'!B6),MONTH('Base Projection Controls'!B6),1),IF(DATE(YEAR('Base Projection Controls'!B6),MONTH('Base Projection Controls'!B6),1)="","",DATE(2027,6,1)=DATE(YEAR('Base Projection Controls'!B6),MONTH('Base Projection Controls'!B6),1)))="",FALSE(),IF(ISERROR(DATE(2027,6,1)=DATE(YEAR('Base Projection Controls'!B6),MONTH('Base Projection Controls'!B6),1)),DATE(2027,6,1)=DATE(YEAR('Base Projection Controls'!B6),MONTH('Base Projection Controls'!B6),1),IF(DATE(YEAR('Base Projection Controls'!B6),MONTH('Base Projection Controls'!B6),1)="","",DATE(2027,6,1)=DATE(YEAR('Base Projection Controls'!B6),MONTH('Base Projection Controls'!B6),1)))),0,IF('Base Monthly Projection'!F13="","",'Base Monthly Projection'!F13)))+'Base Monthly Projection'!G10 -> 2106 | H13: =IF(IF(IF(IF(ISERROR(DATE(2027,7,1)=DATE(YEAR('Base Projection Controls'!B6),MONTH('Base Projection Controls'!B6),1)),DATE(2027,7,1)=DATE(YEAR('Base Projection Controls'!B6),MONTH('Base Projection Controls'!B6),1),IF(DATE(YEAR('Base Projection Controls'!B6),MONTH('Base Projection Controls'!B6),1)="","",DATE(2027,7,1)=DATE(YEAR('Base Projection Controls'!B6),MONTH('Base Projection Controls'!B6),1)))="",FALSE(),IF(ISERROR(DATE(2027,7,1)=DATE(YEAR('Base Projection Controls'!B6),MONTH('Base Projection Controls'!B6),1)),DATE(2027,7,1)=DATE(YEAR('Base Projection Controls'!B6),MONTH('Base Projection Controls'!B6),1),IF(DATE(YEAR('Base Projection Controls'!B6),MONTH('Base Projection Controls'!B6),1)="","",DATE(2027,7,1)=DATE(YEAR('Base Projection Controls'!B6),MONTH('Base Projection Controls'!B6),1)))),0,IF('Base Monthly Projection'!G13="","",'Base Monthly Projection'!G13))="",0,IF(IF(IF(ISERROR(DATE(2027,7,1)=DATE(YEAR('Base Projection Controls'!B6),MONTH('Base Projection Controls'!B6),1)),DATE(2027,7,1)=DATE(YEAR('Base Projection Controls'!B6),MONTH('Base Projection Controls'!B6),1),IF(DATE(YEAR('Base Projection Controls'!B6),MONTH('Base Projection Controls'!B6),1)="","",DATE(2027,7,1)=DATE(YEAR('Base Projection Controls'!B6),MONTH('Base Projection Controls'!B6),1)))="",FALSE(),IF(ISERROR(DATE(2027,7,1)=DATE(YEAR('Base Projection Controls'!B6),MONTH('Base Projection Controls'!B6),1)),DATE(2027,7,1)=DATE(YEAR('Base Projection Controls'!B6),MONTH('Base Projection Controls'!B6),1),IF(DATE(YEAR('Base Projection Controls'!B6),MONTH('Base Projection Controls'!B6),1)="","",DATE(2027,7,1)=DATE(YEAR('Base Projection Controls'!B6),MONTH('Base Projection Controls'!B6),1)))),0,IF('Base Monthly Projection'!G13="","",'Base Monthly Projection'!G13)))+'Base Monthly Projection'!H10 -> 3814 | I13: =IF(IF(IF(IF(ISERROR(DATE(2027,8,1)=DATE(YEAR('Base Projection Controls'!B6),MONTH('Base Projection Controls'!B6),1)),DATE(2027,8,1)=DATE(YEAR('Base Projection Controls'!B6),MONTH('Base Projection Controls'!B6),1),IF(DATE(YEAR('Base Projection Controls'!B6),MONTH('Base Projection Controls'!B6),1)="","",DATE(2027,8,1)=DATE(YEAR('Base Projection Controls'!B6),MONTH('Base Projection Controls'!B6),1)))="",FALSE(),IF(ISERROR(DATE(2027,8,1)=DATE(YEAR('Base Projection Controls'!B6),MONTH('Base Projection Controls'!B6),1)),DATE(2027,8,1)=DATE(YEAR('Base Projection Controls'!B6),MONTH('Base Projection Controls'!B6),1),IF(DATE(YEAR('Base Projection Controls'!B6),MONTH('Base Projection Controls'!B6),1)="","",DATE(2027,8,1)=DATE(YEAR('Base Projection Controls'!B6),MONTH('Base Projection Controls'!B6),1)))),0,IF('Base Monthly Projection'!H13="","",'Base Monthly Projection'!H13))="",0,IF(IF(IF(ISERROR(DATE(2027,8,1)=DATE(YEAR('Base Projection Controls'!B6),MONTH('Base Projection Controls'!B6),1)),DATE(2027,8,1)=DATE(YEAR('Base Projection Controls'!B6),MONTH('Base Projection Controls'!B6),1),IF(DATE(YEAR('Base Projection Controls'!B6),MONTH('Base Projection Controls'!B6),1)="","",DATE(2027,8,1)=DATE(YEAR('Base Projection Controls'!B6),MONTH('Base Projection Controls'!B6),1)))="",FALSE(),IF(ISERROR(DATE(2027,8,1)=DATE(YEAR('Base Projection Controls'!B6),MONTH('Base Projection Controls'!B6),1)),DATE(2027,8,1)=DATE(YEAR('Base Projection Controls'!B6),MONTH('Base Projection Controls'!B6),1),IF(DATE(YEAR('Base Projection Controls'!B6),MONTH('Base Projection Controls'!B6),1)="","",DATE(2027,8,1)=DATE(YEAR('Base Projection Controls'!B6),MONTH('Base Projection Controls'!B6),1)))),0,IF('Base Monthly Projection'!H13="","",'Base Monthly Projection'!H13)))+'Base Monthly Projection'!I10 -> 5936 | J13: =IF(IF(IF(IF(ISERROR(DATE(2027,9,1)=DATE(YEAR('Base Projection Controls'!B6),MONTH('Base Projection Controls'!B6),1)),DATE(2027,9,1)=DATE(YEAR('Base Projection Controls'!B6),MONTH('Base Projection Controls'!B6),1),IF(DATE(YEAR('Base Projection Controls'!B6),MONTH('Base Projection Controls'!B6),1)="","",DATE(2027,9,1)=DATE(YEAR('Base Projection Controls'!B6),MONTH('Base Projection Controls'!B6),1)))="",FALSE(),IF(ISERROR(DATE(2027,9,1)=DATE(YEAR('Base Projection Controls'!B6),MONTH('Base Projection Controls'!B6),1)),DATE(2027,9,1)=DATE(YEAR('Base Projection Controls'!B6),MONTH('Base Projection Controls'!B6),1),IF(DATE(YEAR('Base Projection Controls'!B6),MONTH('Base Projection Controls'!B6),1)="","",DATE(2027,9,1)=DATE(YEAR('Base Projection Controls'!B6),MONTH('Base Projection Controls'!B6),1)))),0,IF('Base Monthly Projection'!I13="","",'Base Monthly Projection'!I13))="",0,IF(IF(IF(ISERROR(DATE(2027,9,1)=DATE(YEAR('Base Projection Controls'!B6),MONTH('Base Projection Controls'!B6),1)),DATE(2027,9,1)=DATE(YEAR('Base Projection Controls'!B6),MONTH('Base Projection Controls'!B6),1),IF(DATE(YEAR('Base Projection Controls'!B6),MONTH('Base Projection Controls'!B6),1)="","",DATE(2027,9,1)=DATE(YEAR('Base Projection Controls'!B6),MONTH('Base Projection Controls'!B6),1)))="",FALSE(),IF(ISERROR(DATE(2027,9,1)=DATE(YEAR('Base Projection Controls'!B6),MONTH('Base Projection Controls'!B6),1)),DATE(2027,9,1)=DATE(YEAR('Base Projection Controls'!B6),MONTH('Base Projection Controls'!B6),1),IF(DATE(YEAR('Base Projection Controls'!B6),MONTH('Base Projection Controls'!B6),1)="","",DATE(2027,9,1)=DATE(YEAR('Base Projection Controls'!B6),MONTH('Base Projection Controls'!B6),1)))),0,IF('Base Monthly Projection'!I13="","",'Base Monthly Projection'!I13)))+'Base Monthly Projection'!J10 -> 8196 | K13: =IF(IF(IF(IF(ISERROR(DATE(2027,10,1)=DATE(YEAR('Base Projection Controls'!B6),MONTH('Base Projection Controls'!B6),1)),DATE(2027,10,1)=DATE(YEAR('Base Projection Controls'!B6),MONTH('Base Projection Controls'!B6),1),IF(DATE(YEAR('Base Projection Controls'!B6),MONTH('Base Projection Controls'!B6),1)="","",DATE(2027,10,1)=DATE(YEAR('Base Projection Controls'!B6),MONTH('Base Projection Controls'!B6),1)))="",FALSE(),IF(ISERROR(DATE(2027,10,1)=DATE(YEAR('Base Projection Controls'!B6),MONTH('Base Projection Controls'!B6),1)),DATE(2027,10,1)=DATE(YEAR('Base Projection Controls'!B6),MONTH('Base Projection Controls'!B6),1),IF(DATE(YEAR('Base Projection Controls'!B6),MONTH('Base Projection Controls'!B6),1)="","",DATE(2027,10,1)=DATE(YEAR('Base Projection Controls'!B6),MONTH('Base Projection Controls'!B6),1)))),0,IF('Base Monthly Projection'!J13="","",'Base Monthly Projection'!J13))="",0,IF(IF(IF(ISERROR(DATE(2027,10,1)=DATE(YEAR('Base Projection Controls'!B6),MONTH('Base Projection Controls'!B6),1)),DATE(2027,10,1)=DATE(YEAR('Base Projection Controls'!B6),MONTH('Base Projection Controls'!B6),1),IF(DATE(YEAR('Base Projection Controls'!B6),MONTH('Base Projection Controls'!B6),1)="","",DATE(2027,10,1)=DATE(YEAR('Base Projection Controls'!B6),MONTH('Base Projection Controls'!B6),1)))="",FALSE(),IF(ISERROR(DATE(2027,10,1)=DATE(YEAR('Base Projection Controls'!B6),MONTH('Base Projection Controls'!B6),1)),DATE(2027,10,1)=DATE(YEAR('Base Projection Controls'!B6),MONTH('Base Projection Controls'!B6),1),IF(DATE(YEAR('Base Projection Controls'!B6),MONTH('Base Projection Controls'!B6),1)="","",DATE(2027,10,1)=DATE(YEAR('Base Projection Controls'!B6),MONTH('Base Projection Controls'!B6),1)))),0,IF('Base Monthly Projection'!J13="","",'Base Monthly Projection'!J13)))+'Base Monthly Projection'!K10 -> 10456 | L13: =IF(IF(IF(IF(ISERROR(DATE(2027,11,1)=DATE(YEAR('Base Projection Controls'!B6),MONTH('Base Projection Controls'!B6),1)),DATE(2027,11,1)=DATE(YEAR('Base Projection Controls'!B6),MONTH('Base Projection Controls'!B6),1),IF(DATE(YEAR('Base Projection Controls'!B6),MONTH('Base Projection Controls'!B6),1)="","",DATE(2027,11,1)=DATE(YEAR('Base Projection Controls'!B6),MONTH('Base Projection Controls'!B6),1)))="",FALSE(),IF(ISERROR(DATE(2027,11,1)=DATE(YEAR('Base Projection Controls'!B6),MONTH('Base Projection Controls'!B6),1)),DATE(2027,11,1)=DATE(YEAR('Base Projection Controls'!B6),MONTH('Base Projection Controls'!B6),1),IF(DATE(YEAR('Base Projection Controls'!B6),MONTH('Base Projection Controls'!B6),1)="","",DATE(2027,11,1)=DATE(YEAR('Base Projection Controls'!B6),MONTH('Base Projection Controls'!B6),1)))),0,IF('Base Monthly Projection'!K13="","",'Base Monthly Projection'!K13))="",0,IF(IF(IF(ISERROR(DATE(2027,11,1)=DATE(YEAR('Base Projection Controls'!B6),MONTH('Base Projection Controls'!B6),1)),DATE(2027,11,1)=DATE(YEAR('Base Projection Controls'!B6),MONTH('Base Projection Controls'!B6),1),IF(DATE(YEAR('Base Projection Controls'!B6),MONTH('Base Projection Controls'!B6),1)="","",DATE(2027,11,1)=DATE(YEAR('Base Projection Controls'!B6),MONTH('Base Projection Controls'!B6),1)))="",FALSE(),IF(ISERROR(DATE(2027,11,1)=DATE(YEAR('Base Projection Controls'!B6),MONTH('Base Projection Controls'!B6),1)),DATE(2027,11,1)=DATE(YEAR('Base Projection Controls'!B6),MONTH('Base Projection Controls'!B6),1),IF(DATE(YEAR('Base Projection Controls'!B6),MONTH('Base Projection Controls'!B6),1)="","",DATE(2027,11,1)=DATE(YEAR('Base Projection Controls'!B6),MONTH('Base Projection Controls'!B6),1)))),0,IF('Base Monthly Projection'!K13="","",'Base Monthly Projection'!K13)))+'Base Monthly Projection'!L10 -> 12716 | M13: =IF(IF(IF(IF(ISERROR(DATE(2027,12,1)=DATE(YEAR('Base Projection Controls'!B6),MONTH('Base Projection Controls'!B6),1)),DATE(2027,12,1)=DATE(YEAR('Base Projection Controls'!B6),MONTH('Base Projection Controls'!B6),1),IF(DATE(YEAR('Base Projection Controls'!B6),MONTH('Base Projection Controls'!B6),1)="","",DATE(2027,12,1)=DATE(YEAR('Base Projection Controls'!B6),MONTH('Base Projection Controls'!B6),1)))="",FALSE(),IF(ISERROR(DATE(2027,12,1)=DATE(YEAR('Base Projection Controls'!B6),MONTH('Base Projection Controls'!B6),1)),DATE(2027,12,1)=DATE(YEAR('Base Projection Controls'!B6),MONTH('Base Projection Controls'!B6),1),IF(DATE(YEAR('Base Projection Controls'!B6),MONTH('Base Projection Controls'!B6),1)="","",DATE(2027,12,1)=DATE(YEAR('Base Projection Controls'!B6),MONTH('Base Projection Controls'!B6),1)))),0,IF('Base Monthly Projection'!L13="","",'Base Monthly Projection'!L13))="",0,IF(IF(IF(ISERROR(DATE(2027,12,1)=DATE(YEAR('Base Projection Controls'!B6),MONTH('Base Projection Controls'!B6),1)),DATE(2027,12,1)=DATE(YEAR('Base Projection Controls'!B6),MONTH('Base Projection Controls'!B6),1),IF(DATE(YEAR('Base Projection Controls'!B6),MONTH('Base Projection Controls'!B6),1)="","",DATE(2027,12,1)=DATE(YEAR('Base Projection Controls'!B6),MONTH('Base Projection Controls'!B6),1)))="",FALSE(),IF(ISERROR(DATE(2027,12,1)=DATE(YEAR('Base Projection Controls'!B6),MONTH('Base Projection Controls'!B6),1)),DATE(2027,12,1)=DATE(YEAR('Base Projection Controls'!B6),MONTH('Base Projection Controls'!B6),1),IF(DATE(YEAR('Base Projection Controls'!B6),MONTH('Base Projection Controls'!B6),1)="","",DATE(2027,12,1)=DATE(YEAR('Base Projection Controls'!B6),MONTH('Base Projection Controls'!B6),1)))),0,IF('Base Monthly Projection'!L13="","",'Base Monthly Projection'!L13)))+'Base Monthly Projection'!M10 -> 14976
A14: Cash Reconciliation Check — Base Projection (EUR) | B14: ='Base Monthly Projection'!B12-('Year 1 Assumptions'!B7+'Base Monthly Projection'!B13) -> 0 | C14: ='Base Monthly Projection'!C12-('Year 1 Assumptions'!B7+'Base Monthly Projection'!C13) -> 0 | D14: ='Base Monthly Projection'!D12-('Year 1 Assumptions'!B7+'Base Monthly Projection'!D13) -> 0 | E14: ='Base Monthly Projection'!E12-('Year 1 Assumptions'!B7+'Base Monthly Projection'!E13) -> 0 | F14: ='Base Monthly Projection'!F12-('Year 1 Assumptions'!B7+'Base Monthly Projection'!F13) -> 0 | G14: ='Base Monthly Projection'!G12-('Year 1 Assumptions'!B7+'Base Monthly Projection'!G13) -> 0 | H14: ='Base Monthly Projection'!H12-('Year 1 Assumptions'!B7+'Base Monthly Projection'!H13) -> 0 | I14: ='Base Monthly Projection'!I12-('Year 1 Assumptions'!B7+'Base Monthly Projection'!I13) -> 0 | J14: ='Base Monthly Projection'!J12-('Year 1 Assumptions'!B7+'Base Monthly Projection'!J13) -> 0 | K14: ='Base Monthly Projection'!K12-('Year 1 Assumptions'!B7+'Base Monthly Projection'!K13) -> 0 | L14: ='Base Monthly Projection'!L12-('Year 1 Assumptions'!B7+'Base Monthly Projection'!L13) -> 0 | M14: ='Base Monthly Projection'!M12-('Year 1 Assumptions'!B7+'Base Monthly Projection'!M13) -> 0

Sheet Base Annual Reconciliation
A1: DisruptRadar — Monthly Projection · Base Annual Reconciliation with the Scenario Matrix
A2: Financial model (2 pages) · Base
A4: Variable / dimension | B4: Value
A5: Customer-Months — Base Projection | B5: =SUM('Base Monthly Projection'!B5,'Base Monthly Projection'!C5,'Base Monthly Projection'!D5,'Base Monthly Projection'!E5,'Base Monthly Projection'!F5,'Base Monthly Projection'!G5,'Base Monthly Projection'!H5,'Base Monthly Projection'!I5,'Base Monthly Projection'!J5,'Base Monthly Projection'!K5,'Base Monthly Projection'!L5,'Base Monthly Projection'!M5) -> 304
A6: Annual Revenue — Base Projection (EUR) | B6: =SUM('Base Monthly Projection'!B6,'Base Monthly Projection'!C6,'Base Monthly Projection'!D6,'Base Monthly Projection'!E6,'Base Monthly Projection'!F6,'Base Monthly Projection'!G6,'Base Monthly Projection'!H6,'Base Monthly Projection'!I6,'Base Monthly Projection'!J6,'Base Monthly Projection'!K6,'Base Monthly Projection'!L6,'Base Monthly Projection'!M6) -> 30096
A7: Annual Delivery Costs — Base Projection (EUR) | B7: =SUM('Base Monthly Projection'!B7,'Base Monthly Projection'!C7,'Base Monthly Projection'!D7,'Base Monthly Projection'!E7,'Base Monthly Projection'!F7,'Base Monthly Projection'!G7,'Base Monthly Projection'!H7,'Base Monthly Projection'!I7,'Base Monthly Projection'!J7,'Base Monthly Projection'!K7,'Base Monthly Projection'!L7,'Base Monthly Projection'!M7) -> 9120
A8: Calculated Annual Fixed Costs — Base Projection (EUR) | B8: =SUM('Base Monthly Projection'!B8,'Base Monthly Projection'!C8,'Base Monthly Projection'!D8,'Base Monthly Projection'!E8,'Base Monthly Projection'!F8,'Base Monthly Projection'!G8,'Base Monthly Projection'!H8,'Base Monthly Projection'!I8,'Base Monthly Projection'!J8,'Base Monthly Projection'!K8,'Base Monthly Projection'!L8,'Base Monthly Projection'!M8) -> 6000
A9: Annual Costs — Base Projection (EUR) | B9: =SUM('Base Monthly Projection'!B9,'Base Monthly Projection'!C9,'Base Monthly Projection'!D9,'Base Monthly Projection'!E9,'Base Monthly Projection'!F9,'Base Monthly Projection'!G9,'Base Monthly Projection'!H9,'Base Monthly Projection'!I9,'Base Monthly Projection'!J9,'Base Monthly Projection'!K9,'Base Monthly Projection'!L9,'Base Monthly Projection'!M9) -> 15120
A10: Annual EBITDA — Base Projection (EUR) | B10: =SUM('Base Monthly Projection'!B10,'Base Monthly Projection'!C10,'Base Monthly Projection'!D10,'Base Monthly Projection'!E10,'Base Monthly Projection'!F10,'Base Monthly Projection'!G10,'Base Monthly Projection'!H10,'Base Monthly Projection'!I10,'Base Monthly Projection'!J10,'Base Monthly Projection'!K10,'Base Monthly Projection'!L10,'Base Monthly Projection'!M10) -> 14976
A11: Minimum Cash — Base Projection (EUR) | B11: =MIN('Base Monthly Projection'!B12,'Base Monthly Projection'!C12,'Base Monthly Projection'!D12,'Base Monthly Projection'!E12,'Base Monthly Projection'!F12,'Base Monthly Projection'!G12,'Base Monthly Projection'!H12,'Base Monthly Projection'!I12,'Base Monthly Projection'!J12,'Base Monthly Projection'!K12,'Base Monthly Projection'!L12,'Base Monthly Projection'!M12) -> 19345
A12: Year-End Cash — Base Projection (EUR) | B12: =IF('Base Monthly Projection'!M12="","",'Base Monthly Projection'!M12) -> 34976
A13: Revenue Difference vs Base Scenario Matrix (EUR) | B13: ='Base Annual Reconciliation'!B6-'Scenario Matrix'!B6 -> 0
A14: Cost Difference vs Base Scenario Matrix (EUR) | B14: ='Base Annual Reconciliation'!B9-'Scenario Matrix'!B7 -> 0
A15: EBITDA Difference vs Base Scenario Matrix (EUR) | B15: ='Base Annual Reconciliation'!B10-'Scenario Matrix'!B8 -> 0

Sheet Fixed Cost Sensitivity
A1: DisruptRadar — Monthly Projection · Base Sensitivity — Monthly Fixed Costs
A2: Financial model (2 pages) · Base
A4: Variable / dimension | B4: Value | C4: Value > Base — Fixed Costs €300/Month | D4: Value > Base — Fixed Costs €400/Month | E4: Value > Base — Fixed Costs €500/Month
A5: Annual Fixed Costs for the Base Projection (EUR) | B5: ='Base Projection Controls'!B5 -> 6000 | C5: =3600 -> 3600 | D5: =4800 -> 4800 | E5: =6000 -> 6000
A6: Annual Costs — Base Projection (EUR) | B6: =SUM('Base Monthly Projection'!B9,'Base Monthly Projection'!C9,'Base Monthly Projection'!D9,'Base Monthly Projection'!E9,'Base Monthly Projection'!F9,'Base Monthly Projection'!G9,'Base Monthly Projection'!H9,'Base Monthly Projection'!I9,'Base Monthly Projection'!J9,'Base Monthly Projection'!K9,'Base Monthly Projection'!L9,'Base Monthly Projection'!M9) -> 15120 | C6: =SUM('Model inputs'!C33,'Model inputs'!D33,'Model inputs'!E33,'Model inputs'!F33,'Model inputs'!G33,'Model inputs'!H33,'Model inputs'!I33,'Model inputs'!J33,'Model inputs'!K33,'Model inputs'!L33,'Model inputs'!M33,'Model inputs'!N33) -> 12720 | D6: =SUM('Model inputs'!C32,'Model inputs'!D32,'Model inputs'!E32,'Model inputs'!F32,'Model inputs'!G32,'Model inputs'!H32,'Model inputs'!I32,'Model inputs'!J32,'Model inputs'!K32,'Model inputs'!L32,'Model inputs'!M32,'Model inputs'!N32) -> 13920 | E6: =SUM('Model inputs'!C34,'Model inputs'!D34,'Model inputs'!E34,'Model inputs'!F34,'Model inputs'!G34,'Model inputs'!H34,'Model inputs'!I34,'Model inputs'!J34,'Model inputs'!K34,'Model inputs'!L34,'Model inputs'!M34,'Model inputs'!N34) -> 15120
A7: Annual EBITDA — Base Projection (EUR) | B7: =SUM('Base Monthly Projection'!B10,'Base Monthly Projection'!C10,'Base Monthly Projection'!D10,'Base Monthly Projection'!E10,'Base Monthly Projection'!F10,'Base Monthly Projection'!G10,'Base Monthly Projection'!H10,'Base Monthly Projection'!I10,'Base Monthly Projection'!J10,'Base Monthly Projection'!K10,'Base Monthly Projection'!L10,'Base Monthly Projection'!M10) -> 14976 | C7: =SUM('Model inputs'!C45,'Model inputs'!D45,'Model inputs'!E45,'Model inputs'!F45,'Model inputs'!G45,'Model inputs'!H45,'Model inputs'!I45,'Model inputs'!J45,'Model inputs'!K45,'Model inputs'!L45,'Model inputs'!M45,'Model inputs'!N45) -> 17376 | D7: =SUM('Model inputs'!C43,'Model inputs'!D43,'Model inputs'!E43,'Model inputs'!F43,'Model inputs'!G43,'Model inputs'!H43,'Model inputs'!I43,'Model inputs'!J43,'Model inputs'!K43,'Model inputs'!L43,'Model inputs'!M43,'Model inputs'!N43) -> 16176 | E7: =SUM('Model inputs'!C48,'Model inputs'!D48,'Model inputs'!E48,'Model inputs'!F48,'Model inputs'!G48,'Model inputs'!H48,'Model inputs'!I48,'Model inputs'!J48,'Model inputs'!K48,'Model inputs'!L48,'Model inputs'!M48,'Model inputs'!N48) -> 14976
A8: Minimum Cash — Base Projection (EUR) | B8: =MIN('Base Monthly Projection'!B12,'Base Monthly Projection'!C12,'Base Monthly Projection'!D12,'Base Monthly Projection'!E12,'Base Monthly Projection'!F12,'Base Monthly Projection'!G12,'Base Monthly Projection'!H12,'Base Monthly Projection'!I12,'Base Monthly Projection'!J12,'Base Monthly Projection'!K12,'Base Monthly Projection'!L12,'Base Monthly Projection'!M12) -> 19345 | C8: =MIN('Model inputs'!C9,'Model inputs'!D9,'Model inputs'!E9,'Model inputs'!F9,'Model inputs'!G9,'Model inputs'!H9,'Model inputs'!I9,'Model inputs'!J9,'Model inputs'!K9,'Model inputs'!L9,'Model inputs'!M9,'Model inputs'!N9) -> 19745 | D8: =MIN('Model inputs'!C8,'Model inputs'!D8,'Model inputs'!E8,'Model inputs'!F8,'Model inputs'!G8,'Model inputs'!H8,'Model inputs'!I8,'Model inputs'!J8,'Model inputs'!K8,'Model inputs'!L8,'Model inputs'!M8,'Model inputs'!N8) -> 19545 | E8: =MIN('Model inputs'!C10,'Model inputs'!D10,'Model inputs'!E10,'Model inputs'!F10,'Model inputs'!G10,'Model inputs'!H10,'Model inputs'!I10,'Model inputs'!J10,'Model inputs'!K10,'Model inputs'!L10,'Model inputs'!M10,'Model inputs'!N10) -> 19345
A9: Year-End Cash — Base Projection (EUR) | B9: =IF('Base Monthly Projection'!M12="","",'Base Monthly Projection'!M12) -> 34976 | C9: =IF('Model inputs'!N9="","",'Model inputs'!N9) -> 37376 | D9: =IF('Model inputs'!N8="","",'Model inputs'!N8) -> 36176 | E9: =IF('Model inputs'!N10="","",'Model inputs'!N10) -> 34976

Sheet Price & Fixed Cost Sensitivity
A1: DisruptRadar — Monthly Projection · Full Sensitivity — Pro Price and Fixed Costs
A2: Financial model (2 pages) · Base
