Workbook

Sheet DisruptRadar Business Plan · Ma
A1: DisruptRadar Business Plan · Matriz de cenários DisruptRadar
A2: Financial model (2 pages) · Base
A4: Variable / dimension | B4: Value | C4: Value > Pessimista | D4: Value > Otimista
A5: Subscritores (fim de ano) | B5: =40 -> 40 | C5: =12 -> 12 | D5: =100 -> 100
A6: Receita anual realizada (EUR) | B6: =30096 -> 30096 | C6: =8000 -> 8000 | D6: =80000 -> 80000
A7: Custos anuais (EUR) | B7: =15120 -> 15120 | C7: =6000 -> 6000 | D7: =24000 -> 24000
A8: EBITDA (EUR) | B8: ='DisruptRadar Business Plan · Ma'!B6-'DisruptRadar Business Plan · Ma'!B7 -> 14976 | C8: ='DisruptRadar Business Plan · Ma'!C6-'DisruptRadar Business Plan · Ma'!C7 -> 2000 | D8: ='DisruptRadar Business Plan · Ma'!D6-'DisruptRadar Business Plan · Ma'!D7 -> 56000
A9: Margem bruta | B9: =0.8 -> 0.8 | C9: =0.75 -> 0.75 | D9: =0.85 -> 0.85
A10: Cobertura de caixa com receita zero (meses) | B10: =IFERROR('DisruptRadar Business Plan · Pr'!B7/'DisruptRadar Business Plan · Ma'!B7*12,"") -> 15.873016 | C10: =IFERROR('Model inputs'!Z13/'DisruptRadar Business Plan · Ma'!C7*12,"") -> 40 | D10: =IFERROR('Model inputs'!Z14/'DisruptRadar Business Plan · Ma'!D7*12,"") -> 10

Sheet DisruptRadar Business Plan · Pr
A1: DisruptRadar Business Plan · Premissas DisruptRadar — Ano 1
A2: Financial model (2 pages) · Base
A4: Variable / dimension | B4: Value
A5: Preço mensal Pro (EUR) | B5: =99 -> 99
A6: Preço mensal Enterprise proposto (EUR) | B6: =499 -> 499
A7: Caixa inicial (EUR) | B7: =20000 -> 20000
A8: Custo fixo mensal (EUR) | B8: =500 -> 500
A9: Mercado endereçável mínimo (contas) | B9: =500 -> 500
A10: Mercado endereçável máximo (contas) | B10: =1000 -> 1000
A11: Custo variável por domínio por mês — estimativa (EUR) | B11: =3 -> 3
A12: Margem Pro após custo variável — um domínio por subscritor | B12: =IFERROR(1-'DisruptRadar Business Plan · Pr'!B11/'DisruptRadar Business Plan · Pr'!B5,"") -> 0.96969697
A13: Domínios incluídos no plano Pro | B13: =10 -> 10
A14: Domínios médios por cliente Pro — hipótese | B14: =10 -> 10
A15: Custo mensal de entrega por cliente Pro (EUR) | B15: ='DisruptRadar Business Plan · Pr'!B14*'DisruptRadar Business Plan · Pr'!B11 -> 30
A16: Margem de contribuição Pro — utilização média | B16: =IFERROR(('DisruptRadar Business Plan · Pr'!B5-'DisruptRadar Business Plan · Pr'!B15)/'DisruptRadar Business Plan · Pr'!B5,"") -> 0.6969697

Sheet DisruptRadar Business Plan · Cu
A1: DisruptRadar Business Plan · Custo de entrega ligado à utilização — referência Pro
A2: Financial model (2 pages) · Base
A4: Variable / dimension | B4: Value | C4: Value > Pessimista | D4: Value > Otimista
A5: Subscritores (fim de ano) | B5: =40 -> 40 | C5: ='DisruptRadar Business Plan · Ma'!C5 -> 12 | D5: ='DisruptRadar Business Plan · Ma'!D5 -> 100
A6: Domínios monitorizados ao fim do ano — referência Pro | B6: ='DisruptRadar Business Plan · Pr'!B14*'DisruptRadar Business Plan · Cu'!B5 -> 400 | C6: ='Model inputs'!Z38*'DisruptRadar Business Plan · Cu'!C5 -> 120 | D6: ='Model inputs'!Z39*'DisruptRadar Business Plan · Cu'!D5 -> 1000
A7: Custo mensal de entrega ao fim do ano — referência Pro (EUR) | B7: ='DisruptRadar Business Plan · Pr'!B14*'DisruptRadar Business Plan · Pr'!B11*'DisruptRadar Business Plan · Cu'!B5 -> 1200 | C7: ='Model inputs'!Z38*'Model inputs'!Z28*'DisruptRadar Business Plan · Cu'!C5 -> 360 | D7: ='Model inputs'!Z39*'Model inputs'!Z29*'DisruptRadar Business Plan · Cu'!D5 -> 3000

Sheet DisruptRadar — Projeção mensal
A1: DisruptRadar — Projeção mensal · Controlos da projeção Base
A2: Financial model (2 pages) · Base
A4: Variable / dimension | B4: Value
A5: Fixos anuais da projeção Base (EUR) | B5: =6000 -> 6000
A6: Início da projeção Base | B6: =DATE(2027,1,1) -> 46388
A7: Preço mensal Pro (EUR) | B7: =99 -> 99
A8: Domínios médios por cliente Pro — hipótese | B8: =10 -> 10
A9: Custo variável por domínio por mês — estimativa (EUR) | B9: =3 -> 3
A10: Caixa inicial (EUR) | B10: =20000 -> 20000

Sheet DisruptRadar — Projeção men (2)
A1: DisruptRadar — Projeção mensal · Projeção mensal Base — clientes, resultado e caixa
A2: Financial model (2 pages) · Base
A4: Variable / dimension | B4: 2027-01 | C4: 2027-02 | D4: 2027-03 | E4: 2027-04 | F4: 2027-05 | G4: 2027-06 | H4: 2027-07 | I4: 2027-08 | J4: 2027-09 | K4: 2027-10 | L4: 2027-11 | M4: 2027-12
A5: Clientes no fim do mês — projeção Base | B5: =1 -> 1 | C5: =4 -> 4 | D5: =9 -> 9 | E5: =14 -> 14 | F5: =20 -> 20 | G5: =26 -> 26 | H5: =32 -> 32 | I5: =38 -> 38 | J5: =40 -> 40 | K5: =40 -> 40 | L5: =40 -> 40 | M5: =40 -> 40
A6: Receita mensal — projeção Base (EUR) | B6: ='DisruptRadar — Projeção men (2)'!B5*'DisruptRadar Business Plan · Pr'!B5 -> 99 | C6: ='DisruptRadar — Projeção men (2)'!C5*'DisruptRadar Business Plan · Pr'!B5 -> 396 | D6: ='DisruptRadar — Projeção men (2)'!D5*'DisruptRadar Business Plan · Pr'!B5 -> 891 | E6: ='DisruptRadar — Projeção men (2)'!E5*'DisruptRadar Business Plan · Pr'!B5 -> 1386 | F6: ='DisruptRadar — Projeção men (2)'!F5*'DisruptRadar Business Plan · Pr'!B5 -> 1980 | G6: ='DisruptRadar — Projeção men (2)'!G5*'DisruptRadar Business Plan · Pr'!B5 -> 2574 | H6: ='DisruptRadar — Projeção men (2)'!H5*'DisruptRadar Business Plan · Pr'!B5 -> 3168 | I6: ='DisruptRadar — Projeção men (2)'!I5*'DisruptRadar Business Plan · Pr'!B5 -> 3762 | J6: ='DisruptRadar — Projeção men (2)'!J5*'DisruptRadar Business Plan · Pr'!B5 -> 3960 | K6: ='DisruptRadar — Projeção men (2)'!K5*'DisruptRadar Business Plan · Pr'!B5 -> 3960 | L6: ='DisruptRadar — Projeção men (2)'!L5*'DisruptRadar Business Plan · Pr'!B5 -> 3960 | M6: ='DisruptRadar — Projeção men (2)'!M5*'DisruptRadar Business Plan · Pr'!B5 -> 3960
A7: Entrega mensal — projeção Base (EUR) | B7: ='DisruptRadar — Projeção men (2)'!B5*'DisruptRadar Business Plan · Pr'!B14*'DisruptRadar Business Plan · Pr'!B11 -> 30 | C7: ='DisruptRadar — Projeção men (2)'!C5*'DisruptRadar Business Plan · Pr'!B14*'DisruptRadar Business Plan · Pr'!B11 -> 120 | D7: ='DisruptRadar — Projeção men (2)'!D5*'DisruptRadar Business Plan · Pr'!B14*'DisruptRadar Business Plan · Pr'!B11 -> 270 | E7: ='DisruptRadar — Projeção men (2)'!E5*'DisruptRadar Business Plan · Pr'!B14*'DisruptRadar Business Plan · Pr'!B11 -> 420 | F7: ='DisruptRadar — Projeção men (2)'!F5*'DisruptRadar Business Plan · Pr'!B14*'DisruptRadar Business Plan · Pr'!B11 -> 600 | G7: ='DisruptRadar — Projeção men (2)'!G5*'DisruptRadar Business Plan · Pr'!B14*'DisruptRadar Business Plan · Pr'!B11 -> 780 | H7: ='DisruptRadar — Projeção men (2)'!H5*'DisruptRadar Business Plan · Pr'!B14*'DisruptRadar Business Plan · Pr'!B11 -> 960 | I7: ='DisruptRadar — Projeção men (2)'!I5*'DisruptRadar Business Plan · Pr'!B14*'DisruptRadar Business Plan · Pr'!B11 -> 1140 | J7: ='DisruptRadar — Projeção men (2)'!J5*'DisruptRadar Business Plan · Pr'!B14*'DisruptRadar Business Plan · Pr'!B11 -> 1200 | K7: ='DisruptRadar — Projeção men (2)'!K5*'DisruptRadar Business Plan · Pr'!B14*'DisruptRadar Business Plan · Pr'!B11 -> 1200 | L7: ='DisruptRadar — Projeção men (2)'!L5*'DisruptRadar Business Plan · Pr'!B14*'DisruptRadar Business Plan · Pr'!B11 -> 1200 | M7: ='DisruptRadar — Projeção men (2)'!M5*'DisruptRadar Business Plan · Pr'!B14*'DisruptRadar Business Plan · Pr'!B11 -> 1200
A8: Fixos mensais — projeção Base (EUR) | B8: ='DisruptRadar — Projeção mensal'!B5/12 -> 500 | C8: ='DisruptRadar — Projeção mensal'!B5/12 -> 500 | D8: ='DisruptRadar — Projeção mensal'!B5/12 -> 500 | E8: ='DisruptRadar — Projeção mensal'!B5/12 -> 500 | F8: ='DisruptRadar — Projeção mensal'!B5/12 -> 500 | G8: ='DisruptRadar — Projeção mensal'!B5/12 -> 500 | H8: ='DisruptRadar — Projeção mensal'!B5/12 -> 500 | I8: ='DisruptRadar — Projeção mensal'!B5/12 -> 500 | J8: ='DisruptRadar — Projeção mensal'!B5/12 -> 500 | K8: ='DisruptRadar — Projeção mensal'!B5/12 -> 500 | L8: ='DisruptRadar — Projeção mensal'!B5/12 -> 500 | M8: ='DisruptRadar — Projeção mensal'!B5/12 -> 500
A9: Custos totais mensais — projeção Base (EUR) | B9: ='DisruptRadar — Projeção men (2)'!B7+'DisruptRadar — Projeção men (2)'!B8 -> 530 | C9: ='DisruptRadar — Projeção men (2)'!C7+'DisruptRadar — Projeção men (2)'!C8 -> 620 | D9: ='DisruptRadar — Projeção men (2)'!D7+'DisruptRadar — Projeção men (2)'!D8 -> 770 | E9: ='DisruptRadar — Projeção men (2)'!E7+'DisruptRadar — Projeção men (2)'!E8 -> 920 | F9: ='DisruptRadar — Projeção men (2)'!F7+'DisruptRadar — Projeção men (2)'!F8 -> 1100 | G9: ='DisruptRadar — Projeção men (2)'!G7+'DisruptRadar — Projeção men (2)'!G8 -> 1280 | H9: ='DisruptRadar — Projeção men (2)'!H7+'DisruptRadar — Projeção men (2)'!H8 -> 1460 | I9: ='DisruptRadar — Projeção men (2)'!I7+'DisruptRadar — Projeção men (2)'!I8 -> 1640 | ... M9: ='DisruptRadar — Projeção men (2)'!M7+'DisruptRadar — Projeção men (2)'!M8 -> 1700
A10: EBITDA mensal — projeção Base (EUR) | B10: ='DisruptRadar — Projeção men (2)'!B6-'DisruptRadar — Projeção men (2)'!B9 -> -431 | C10: ='DisruptRadar — Projeção men (2)'!C6-'DisruptRadar — Projeção men (2)'!C9 -> -224 | D10: ='DisruptRadar — Projeção men (2)'!D6-'DisruptRadar — Projeção men (2)'!D9 -> 121 | E10: ='DisruptRadar — Projeção men (2)'!E6-'DisruptRadar — Projeção men (2)'!E9 -> 466 | F10: ='DisruptRadar — Projeção men (2)'!F6-'DisruptRadar — Projeção men (2)'!F9 -> 880 | G10: ='DisruptRadar — Projeção men (2)'!G6-'DisruptRadar — Projeção men (2)'!G9 -> 1294 | H10: ='DisruptRadar — Projeção men (2)'!H6-'DisruptRadar — Projeção men (2)'!H9 -> 1708 | I10: ='DisruptRadar — Projeção men (2)'!I6-'DisruptRadar — Projeção men (2)'!I9 -> 2122 | ... M10: ='DisruptRadar — Projeção men (2)'!M6-'DisruptRadar — Projeção men (2)'!M9 -> 2260
A11: Caixa inicial do mês — projeção Base (EUR) | B11: =IF(IF(IF(ISERROR(DATE(2027,1,1)=DATE(YEAR('DisruptRadar — Projeção mensal'!B6),MONTH('DisruptRadar — Projeção mensal'!B6),1)),DATE(2027,1,1)=DATE(YEAR('DisruptRadar — Projeção mensal'!B6),MONTH('DisruptRadar — Projeção mensal'!B6),1),IF(DATE(YEAR('DisruptRadar — Projeção mensal'!B6),MONTH('DisruptRadar — Projeção mensal'!B6),1)="","",DATE(2027,1,1)=DATE(YEAR('DisruptRadar — Projeção mensal'!B6),MONTH('DisruptRadar — Projeção mensal'!B6),1)))="",FALSE,IF(ISERROR(DATE(2027,1,1)=DATE(YEAR('DisruptRadar — Projeção mensal'!B6),MONTH('DisruptRadar — Projeção mensal'!B6),1)),DATE(2027,1,1)=DATE(YEAR('DisruptRadar — Projeção mensal'!B6),MONTH('DisruptRadar — Projeção mensal'!B6),1),IF(DATE(YEAR('DisruptRadar — Projeção mensal'!B6),MONTH('DisruptRadar — Projeção mensal'!B6),1)="","",DATE(2027,1,1)=DATE(YEAR('DisruptRadar — Projeção mensal'!B6),MONTH('DisruptRadar — Projeção mensal'!B6),1)))),IF('DisruptRadar Business Plan · Pr'!B7="","",'DisruptRadar Business Plan · Pr'!B7),IF('Model inputs'!B6="","",'Model inputs'!B6)) -> 20000 | C11: =IF(IF(IF(ISERROR(DATE(2027,2,1)=DATE(YEAR('DisruptRadar — Projeção mensal'!B6),MONTH('DisruptRadar — Projeção mensal'!B6),1)),DATE(2027,2,1)=DATE(YEAR('DisruptRadar — Projeção mensal'!B6),MONTH('DisruptRadar — Projeção mensal'!B6),1),IF(DATE(YEAR('DisruptRadar — Projeção mensal'!B6),MONTH('DisruptRadar — Projeção mensal'!B6),1)="","",DATE(2027,2,1)=DATE(YEAR('DisruptRadar — Projeção mensal'!B6),MONTH('DisruptRadar — Projeção mensal'!B6),1)))="",FALSE,IF(ISERROR(DATE(2027,2,1)=DATE(YEAR('DisruptRadar — Projeção mensal'!B6),MONTH('DisruptRadar — Projeção mensal'!B6),1)),DATE(2027,2,1)=DATE(YEAR('DisruptRadar — Projeção mensal'!B6),MONTH('DisruptRadar — Projeção mensal'!B6),1),IF(DATE(YEAR('DisruptRadar — Projeção mensal'!B6),MONTH('DisruptRadar — Projeção mensal'!B6),1)="","",DATE(2027,2,1)=DATE(YEAR('DisruptRadar — Projeção mensal'!B6),MONTH('DisruptRadar — Projeção mensal'!B6),1)))),IF('DisruptRadar Business Plan · Pr'!B7="","",'DisruptRadar Business Plan · Pr'!B7),IF('DisruptRadar — Projeção men (2)'!B12="","",'DisruptRadar — Projeção men (2)'!B12)) -> 19569 | D11: =IF(IF(IF(ISERROR(DATE(2027,3,1)=DATE(YEAR('DisruptRadar — Projeção mensal'!B6),MONTH('DisruptRadar — Projeção mensal'!B6),1)),DATE(2027,3,1)=DATE(YEAR('DisruptRadar — Projeção mensal'!B6),MONTH('DisruptRadar — Projeção mensal'!B6),1),IF(DATE(YEAR('DisruptRadar — Projeção mensal'!B6),MONTH('DisruptRadar — Projeção mensal'!B6),1)="","",DATE(2027,3,1)=DATE(YEAR('DisruptRadar — Projeção mensal'!B6),MONTH('DisruptRadar — Projeção mensal'!B6),1)))="",FALSE,IF(ISERROR(DATE(2027,3,1)=DATE(YEAR('DisruptRadar — Projeção mensal'!B6),MONTH('DisruptRadar — Projeção mensal'!B6),1)),DATE(2027,3,1)=DATE(YEAR('DisruptRadar — Projeção mensal'!B6),MONTH('DisruptRadar — Projeção mensal'!B6),1),IF(DATE(YEAR('DisruptRadar — Projeção mensal'!B6),MONTH('DisruptRadar — Projeção mensal'!B6),1)="","",DATE(2027,3,1)=DATE(YEAR('DisruptRadar — Projeção mensal'!B6),MONTH('DisruptRadar — Projeção mensal'!B6),1)))),IF('DisruptRadar Business Plan · Pr'!B7="","",'DisruptRadar Business Plan · Pr'!B7),IF('DisruptRadar — Projeção men (2)'!C12="","",'DisruptRadar — Projeção men (2)'!C12)) -> 19345 | E11: =IF(IF(IF(ISERROR(DATE(2027,4,1)=DATE(YEAR('DisruptRadar — Projeção mensal'!B6),MONTH('DisruptRadar — Projeção mensal'!B6),1)),DATE(2027,4,1)=DATE(YEAR('DisruptRadar — Projeção mensal'!B6),MONTH('DisruptRadar — Projeção mensal'!B6),1),IF(DATE(YEAR('DisruptRadar — Projeção mensal'!B6),MONTH('DisruptRadar — Projeção mensal'!B6),1)="","",DATE(2027,4,1)=DATE(YEAR('DisruptRadar — Projeção mensal'!B6),MONTH('DisruptRadar — Projeção mensal'!B6),1)))="",FALSE,IF(ISERROR(DATE(2027,4,1)=DATE(YEAR('DisruptRadar — Projeção mensal'!B6),MONTH('DisruptRadar — Projeção mensal'!B6),1)),DATE(2027,4,1)=DATE(YEAR('DisruptRadar — Projeção mensal'!B6),MONTH('DisruptRadar — Projeção mensal'!B6),1),IF(DATE(YEAR('DisruptRadar — Projeção mensal'!B6),MONTH('DisruptRadar — Projeção mensal'!B6),1)="","",DATE(2027,4,1)=DATE(YEAR('DisruptRadar — Projeção mensal'!B6),MONTH('DisruptRadar — Projeção mensal'!B6),1)))),IF('DisruptRadar Business Plan · Pr'!B7="","",'DisruptRadar Business Plan · Pr'!B7),IF('DisruptRadar — Projeção men (2)'!D12="","",'DisruptRadar — Projeção men (2)'!D12)) -> 19466 | F11: =IF(IF(IF(ISERROR(DATE(2027,5,1)=DATE(YEAR('DisruptRadar — Projeção mensal'!B6),MONTH('DisruptRadar — Projeção mensal'!B6),1)),DATE(2027,5,1)=DATE(YEAR('DisruptRadar — Projeção mensal'!B6),MONTH('DisruptRadar — Projeção mensal'!B6),1),IF(DATE(YEAR('DisruptRadar — Projeção mensal'!B6),MONTH('DisruptRadar — Projeção mensal'!B6),1)="","",DATE(2027,5,1)=DATE(YEAR('DisruptRadar — Projeção mensal'!B6),MONTH('DisruptRadar — Projeção mensal'!B6),1)))="",FALSE,IF(ISERROR(DATE(2027,5,1)=DATE(YEAR('DisruptRadar — Projeção mensal'!B6),MONTH('DisruptRadar — Projeção mensal'!B6),1)),DATE(2027,5,1)=DATE(YEAR('DisruptRadar — Projeção mensal'!B6),MONTH('DisruptRadar — Projeção mensal'!B6),1),IF(DATE(YEAR('DisruptRadar — Projeção mensal'!B6),MONTH('DisruptRadar — Projeção mensal'!B6),1)="","",DATE(2027,5,1)=DATE(YEAR('DisruptRadar — Projeção mensal'!B6),MONTH('DisruptRadar — Projeção mensal'!B6),1)))),IF('DisruptRadar Business Plan · Pr'!B7="","",'DisruptRadar Business Plan · Pr'!B7),IF('DisruptRadar — Projeção men (2)'!E12="","",'DisruptRadar — Projeção men (2)'!E12)) -> 19932 | G11: =IF(IF(IF(ISERROR(DATE(2027,6,1)=DATE(YEAR('DisruptRadar — Projeção mensal'!B6),MONTH('DisruptRadar — Projeção mensal'!B6),1)),DATE(2027,6,1)=DATE(YEAR('DisruptRadar — Projeção mensal'!B6),MONTH('DisruptRadar — Projeção mensal'!B6),1),IF(DATE(YEAR('DisruptRadar — Projeção mensal'!B6),MONTH('DisruptRadar — Projeção mensal'!B6),1)="","",DATE(2027,6,1)=DATE(YEAR('DisruptRadar — Projeção mensal'!B6),MONTH('DisruptRadar — Projeção mensal'!B6),1)))="",FALSE,IF(ISERROR(DATE(2027,6,1)=DATE(YEAR('DisruptRadar — Projeção mensal'!B6),MONTH('DisruptRadar — Projeção mensal'!B6),1)),DATE(2027,6,1)=DATE(YEAR('DisruptRadar — Projeção mensal'!B6),MONTH('DisruptRadar — Projeção mensal'!B6),1),IF(DATE(YEAR('DisruptRadar — Projeção mensal'!B6),MONTH('DisruptRadar — Projeção mensal'!B6),1)="","",DATE(2027,6,1)=DATE(YEAR('DisruptRadar — Projeção mensal'!B6),MONTH('DisruptRadar — Projeção mensal'!B6),1)))),IF('DisruptRadar Business Plan · Pr'!B7="","",'DisruptRadar Business Plan · Pr'!B7),IF('DisruptRadar — Projeção men (2)'!F12="","",'DisruptRadar — Projeção men (2)'!F12)) -> 20812 | H11: =IF(IF(IF(ISERROR(DATE(2027,7,1)=DATE(YEAR('DisruptRadar — Projeção mensal'!B6),MONTH('DisruptRadar — Projeção mensal'!B6),1)),DATE(2027,7,1)=DATE(YEAR('DisruptRadar — Projeção mensal'!B6),MONTH('DisruptRadar — Projeção mensal'!B6),1),IF(DATE(YEAR('DisruptRadar — Projeção mensal'!B6),MONTH('DisruptRadar — Projeção mensal'!B6),1)="","",DATE(2027,7,1)=DATE(YEAR('DisruptRadar — Projeção mensal'!B6),MONTH('DisruptRadar — Projeção mensal'!B6),1)))="",FALSE,IF(ISERROR(DATE(2027,7,1)=DATE(YEAR('DisruptRadar — Projeção mensal'!B6),MONTH('DisruptRadar — Projeção mensal'!B6),1)),DATE(2027,7,1)=DATE(YEAR('DisruptRadar — Projeção mensal'!B6),MONTH('DisruptRadar — Projeção mensal'!B6),1),IF(DATE(YEAR('DisruptRadar — Projeção mensal'!B6),MONTH('DisruptRadar — Projeção mensal'!B6),1)="","",DATE(2027,7,1)=DATE(YEAR('DisruptRadar — Projeção mensal'!B6),MONTH('DisruptRadar — Projeção mensal'!B6),1)))),IF('DisruptRadar Business Plan · Pr'!B7="","",'DisruptRadar Business Plan · Pr'!B7),IF('DisruptRadar — Projeção men (2)'!G12="","",'DisruptRadar — Projeção men (2)'!G12)) -> 22106 | I11: =IF(IF(IF(ISERROR(DATE(2027,8,1)=DATE(YEAR('DisruptRadar — Projeção mensal'!B6),MONTH('DisruptRadar — Projeção mensal'!B6),1)),DATE(2027,8,1)=DATE(YEAR('DisruptRadar — Projeção mensal'!B6),MONTH('DisruptRadar — Projeção mensal'!B6),1),IF(DATE(YEAR('DisruptRadar — Projeção mensal'!B6),MONTH('DisruptRadar — Projeção mensal'!B6),1)="","",DATE(2027,8,1)=DATE(YEAR('DisruptRadar — Projeção mensal'!B6),MONTH('DisruptRadar — Projeção mensal'!B6),1)))="",FALSE,IF(ISERROR(DATE(2027,8,1)=DATE(YEAR('DisruptRadar — Projeção mensal'!B6),MONTH('DisruptRadar — Projeção mensal'!B6),1)),DATE(2027,8,1)=DATE(YEAR('DisruptRadar — Projeção mensal'!B6),MONTH('DisruptRadar — Projeção mensal'!B6),1),IF(DATE(YEAR('DisruptRadar — Projeção mensal'!B6),MONTH('DisruptRadar — Projeção mensal'!B6),1)="","",DATE(2027,8,1)=DATE(YEAR('DisruptRadar — Projeção mensal'!B6),MONTH('DisruptRadar — Projeção mensal'!B6),1)))),IF('DisruptRadar Business Plan · Pr'!B7="","",'DisruptRadar Business Plan · Pr'!B7),IF('DisruptRadar — Projeção men (2)'!H12="","",'DisruptRadar — Projeção men (2)'!H12)) -> 23814 | J11: =IF(IF(IF(ISERROR(DATE(2027,9,1)=DATE(YEAR('DisruptRadar — Projeção mensal'!B6),MONTH('DisruptRadar — Projeção mensal'!B6),1)),DATE(2027,9,1)=DATE(YEAR('DisruptRadar — Projeção mensal'!B6),MONTH('DisruptRadar — Projeção mensal'!B6),1),IF(DATE(YEAR('DisruptRadar — Projeção mensal'!B6),MONTH('DisruptRadar — Projeção mensal'!B6),1)="","",DATE(2027,9,1)=DATE(YEAR('DisruptRadar — Projeção mensal'!B6),MONTH('DisruptRadar — Projeção mensal'!B6),1)))="",FALSE,IF(ISERROR(DATE(2027,9,1)=DATE(YEAR('DisruptRadar — Projeção mensal'!B6),MONTH('DisruptRadar — Projeção mensal'!B6),1)),DATE(2027,9,1)=DATE(YEAR('DisruptRadar — Projeção mensal'!B6),MONTH('DisruptRadar — Projeção mensal'!B6),1),IF(DATE(YEAR('DisruptRadar — Projeção mensal'!B6),MONTH('DisruptRadar — Projeção mensal'!B6),1)="","",DATE(2027,9,1)=DATE(YEAR('DisruptRadar — Projeção mensal'!B6),MONTH('DisruptRadar — Projeção mensal'!B6),1)))),IF('DisruptRadar Business Plan · Pr'!B7="","",'DisruptRadar Business Plan · Pr'!B7),IF('DisruptRadar — Projeção men (2)'!I12="","",'DisruptRadar — Projeção men (2)'!I12)) -> 25936 | K11: =IF(IF(IF(ISERROR(DATE(2027,10,1)=DATE(YEAR('DisruptRadar — Projeção mensal'!B6),MONTH('DisruptRadar — Projeção mensal'!B6),1)),DATE(2027,10,1)=DATE(YEAR('DisruptRadar — Projeção mensal'!B6),MONTH('DisruptRadar — Projeção mensal'!B6),1),IF(DATE(YEAR('DisruptRadar — Projeção mensal'!B6),MONTH('DisruptRadar — Projeção mensal'!B6),1)="","",DATE(2027,10,1)=DATE(YEAR('DisruptRadar — Projeção mensal'!B6),MONTH('DisruptRadar — Projeção mensal'!B6),1)))="",FALSE,IF(ISERROR(DATE(2027,10,1)=DATE(YEAR('DisruptRadar — Projeção mensal'!B6),MONTH('DisruptRadar — Projeção mensal'!B6),1)),DATE(2027,10,1)=DATE(YEAR('DisruptRadar — Projeção mensal'!B6),MONTH('DisruptRadar — Projeção mensal'!B6),1),IF(DATE(YEAR('DisruptRadar — Projeção mensal'!B6),MONTH('DisruptRadar — Projeção mensal'!B6),1)="","",DATE(2027,10,1)=DATE(YEAR('DisruptRadar — Projeção mensal'!B6),MONTH('DisruptRadar — Projeção mensal'!B6),1)))),IF('DisruptRadar Business Plan · Pr'!B7="","",'DisruptRadar Business Plan · Pr'!B7),IF('DisruptRadar — Projeção men (2)'!J12="","",'DisruptRadar — Projeção men (2)'!J12)) -> 28196 | L11: =IF(IF(IF(ISERROR(DATE(2027,11,1)=DATE(YEAR('DisruptRadar — Projeção mensal'!B6),MONTH('DisruptRadar — Projeção mensal'!B6),1)),DATE(2027,11,1)=DATE(YEAR('DisruptRadar — Projeção mensal'!B6),MONTH('DisruptRadar — Projeção mensal'!B6),1),IF(DATE(YEAR('DisruptRadar — Projeção mensal'!B6),MONTH('DisruptRadar — Projeção mensal'!B6),1)="","",DATE(2027,11,1)=DATE(YEAR('DisruptRadar — Projeção mensal'!B6),MONTH('DisruptRadar — Projeção mensal'!B6),1)))="",FALSE,IF(ISERROR(DATE(2027,11,1)=DATE(YEAR('DisruptRadar — Projeção mensal'!B6),MONTH('DisruptRadar — Projeção mensal'!B6),1)),DATE(2027,11,1)=DATE(YEAR('DisruptRadar — Projeção mensal'!B6),MONTH('DisruptRadar — Projeção mensal'!B6),1),IF(DATE(YEAR('DisruptRadar — Projeção mensal'!B6),MONTH('DisruptRadar — Projeção mensal'!B6),1)="","",DATE(2027,11,1)=DATE(YEAR('DisruptRadar — Projeção mensal'!B6),MONTH('DisruptRadar — Projeção mensal'!B6),1)))),IF('DisruptRadar Business Plan · Pr'!B7="","",'DisruptRadar Business Plan · Pr'!B7),IF('DisruptRadar — Projeção men (2)'!K12="","",'DisruptRadar — Projeção men (2)'!K12)) -> 30456 | M11: =IF(IF(IF(ISERROR(DATE(2027,12,1)=DATE(YEAR('DisruptRadar — Projeção mensal'!B6),MONTH('DisruptRadar — Projeção mensal'!B6),1)),DATE(2027,12,1)=DATE(YEAR('DisruptRadar — Projeção mensal'!B6),MONTH('DisruptRadar — Projeção mensal'!B6),1),IF(DATE(YEAR('DisruptRadar — Projeção mensal'!B6),MONTH('DisruptRadar — Projeção mensal'!B6),1)="","",DATE(2027,12,1)=DATE(YEAR('DisruptRadar — Projeção mensal'!B6),MONTH('DisruptRadar — Projeção mensal'!B6),1)))="",FALSE,IF(ISERROR(DATE(2027,12,1)=DATE(YEAR('DisruptRadar — Projeção mensal'!B6),MONTH('DisruptRadar — Projeção mensal'!B6),1)),DATE(2027,12,1)=DATE(YEAR('DisruptRadar — Projeção mensal'!B6),MONTH('DisruptRadar — Projeção mensal'!B6),1),IF(DATE(YEAR('DisruptRadar — Projeção mensal'!B6),MONTH('DisruptRadar — Projeção mensal'!B6),1)="","",DATE(2027,12,1)=DATE(YEAR('DisruptRadar — Projeção mensal'!B6),MONTH('DisruptRadar — Projeção mensal'!B6),1)))),IF('DisruptRadar Business Plan · Pr'!B7="","",'DisruptRadar Business Plan · Pr'!B7),IF('DisruptRadar — Projeção men (2)'!L12="","",'DisruptRadar — Projeção men (2)'!L12)) -> 32716
A12: Caixa final — projeção Base (EUR) | B12: ='DisruptRadar — Projeção men (2)'!B11+'DisruptRadar — Projeção men (2)'!B10 -> 19569 | C12: ='DisruptRadar — Projeção men (2)'!C11+'DisruptRadar — Projeção men (2)'!C10 -> 19345 | D12: ='DisruptRadar — Projeção men (2)'!D11+'DisruptRadar — Projeção men (2)'!D10 -> 19466 | E12: ='DisruptRadar — Projeção men (2)'!E11+'DisruptRadar — Projeção men (2)'!E10 -> 19932 | F12: ='DisruptRadar — Projeção men (2)'!F11+'DisruptRadar — Projeção men (2)'!F10 -> 20812 | G12: ='DisruptRadar — Projeção men (2)'!G11+'DisruptRadar — Projeção men (2)'!G10 -> 22106 | H12: ='DisruptRadar — Projeção men (2)'!H11+'DisruptRadar — Projeção men (2)'!H10 -> 23814 | I12: ='DisruptRadar — Projeção men (2)'!I11+'DisruptRadar — Projeção men (2)'!I10 -> 25936 | ... M12: ='DisruptRadar — Projeção men (2)'!M11+'DisruptRadar — Projeção men (2)'!M10 -> 34976
A13: Movimento de caixa acumulado — projeção Base (EUR) | B13: =IF(IF(IF(IF(ISERROR(DATE(2027,1,1)=DATE(YEAR('DisruptRadar — Projeção mensal'!B6),MONTH('DisruptRadar — Projeção mensal'!B6),1)),DATE(2027,1,1)=DATE(YEAR('DisruptRadar — Projeção mensal'!B6),MONTH('DisruptRadar — Projeção mensal'!B6),1),IF(DATE(YEAR('DisruptRadar — Projeção mensal'!B6),MONTH('DisruptRadar — Projeção mensal'!B6),1)="","",DATE(2027,1,1)=DATE(YEAR('DisruptRadar — Projeção mensal'!B6),MONTH('DisruptRadar — Projeção mensal'!B6),1)))="",FALSE,IF(ISERROR(DATE(2027,1,1)=DATE(YEAR('DisruptRadar — Projeção mensal'!B6),MONTH('DisruptRadar — Projeção mensal'!B6),1)),DATE(2027,1,1)=DATE(YEAR('DisruptRadar — Projeção mensal'!B6),MONTH('DisruptRadar — Projeção mensal'!B6),1),IF(DATE(YEAR('DisruptRadar — Projeção mensal'!B6),MONTH('DisruptRadar — Projeção mensal'!B6),1)="","",DATE(2027,1,1)=DATE(YEAR('DisruptRadar — Projeção mensal'!B6),MONTH('DisruptRadar — Projeção mensal'!B6),1)))),0,IF('Model inputs'!B64="","",'Model inputs'!B64))="",0,IF(IF(IF(ISERROR(DATE(2027,1,1)=DATE(YEAR('DisruptRadar — Projeção mensal'!B6),MONTH('DisruptRadar — Projeção mensal'!B6),1)),DATE(2027,1,1)=DATE(YEAR('DisruptRadar — Projeção mensal'!B6),MONTH('DisruptRadar — Projeção mensal'!B6),1),IF(DATE(YEAR('DisruptRadar — Projeção mensal'!B6),MONTH('DisruptRadar — Projeção mensal'!B6),1)="","",DATE(2027,1,1)=DATE(YEAR('DisruptRadar — Projeção mensal'!B6),MONTH('DisruptRadar — Projeção mensal'!B6),1)))="",FALSE,IF(ISERROR(DATE(2027,1,1)=DATE(YEAR('DisruptRadar — Projeção mensal'!B6),MONTH('DisruptRadar — Projeção mensal'!B6),1)),DATE(2027,1,1)=DATE(YEAR('DisruptRadar — Projeção mensal'!B6),MONTH('DisruptRadar — Projeção mensal'!B6),1),IF(DATE(YEAR('DisruptRadar — Projeção mensal'!B6),MONTH('DisruptRadar — Projeção mensal'!B6),1)="","",DATE(2027,1,1)=DATE(YEAR('DisruptRadar — Projeção mensal'!B6),MONTH('DisruptRadar — Projeção mensal'!B6),1)))),0,IF('Model inputs'!B64="","",'Model inputs'!B64)))+'DisruptRadar — Projeção men (2)'!B10 -> -431 | C13: =IF(IF(IF(IF(ISERROR(DATE(2027,2,1)=DATE(YEAR('DisruptRadar — Projeção mensal'!B6),MONTH('DisruptRadar — Projeção mensal'!B6),1)),DATE(2027,2,1)=DATE(YEAR('DisruptRadar — Projeção mensal'!B6),MONTH('DisruptRadar — Projeção mensal'!B6),1),IF(DATE(YEAR('DisruptRadar — Projeção mensal'!B6),MONTH('DisruptRadar — Projeção mensal'!B6),1)="","",DATE(2027,2,1)=DATE(YEAR('DisruptRadar — Projeção mensal'!B6),MONTH('DisruptRadar — Projeção mensal'!B6),1)))="",FALSE,IF(ISERROR(DATE(2027,2,1)=DATE(YEAR('DisruptRadar — Projeção mensal'!B6),MONTH('DisruptRadar — Projeção mensal'!B6),1)),DATE(2027,2,1)=DATE(YEAR('DisruptRadar — Projeção mensal'!B6),MONTH('DisruptRadar — Projeção mensal'!B6),1),IF(DATE(YEAR('DisruptRadar — Projeção mensal'!B6),MONTH('DisruptRadar — Projeção mensal'!B6),1)="","",DATE(2027,2,1)=DATE(YEAR('DisruptRadar — Projeção mensal'!B6),MONTH('DisruptRadar — Projeção mensal'!B6),1)))),0,IF('DisruptRadar — Projeção men (2)'!B13="","",'DisruptRadar — Projeção men (2)'!B13))="",0,IF(IF(IF(ISERROR(DATE(2027,2,1)=DATE(YEAR('DisruptRadar — Projeção mensal'!B6),MONTH('DisruptRadar — Projeção mensal'!B6),1)),DATE(2027,2,1)=DATE(YEAR('DisruptRadar — Projeção mensal'!B6),MONTH('DisruptRadar — Projeção mensal'!B6),1),IF(DATE(YEAR('DisruptRadar — Projeção mensal'!B6),MONTH('DisruptRadar — Projeção mensal'!B6),1)="","",DATE(2027,2,1)=DATE(YEAR('DisruptRadar — Projeção mensal'!B6),MONTH('DisruptRadar — Projeção mensal'!B6),1)))="",FALSE,IF(ISERROR(DATE(2027,2,1)=DATE(YEAR('DisruptRadar — Projeção mensal'!B6),MONTH('DisruptRadar — Projeção mensal'!B6),1)),DATE(2027,2,1)=DATE(YEAR('DisruptRadar — Projeção mensal'!B6),MONTH('DisruptRadar — Projeção mensal'!B6),1),IF(DATE(YEAR('DisruptRadar — Projeção mensal'!B6),MONTH('DisruptRadar — Projeção mensal'!B6),1)="","",DATE(2027,2,1)=DATE(YEAR('DisruptRadar — Projeção mensal'!B6),MONTH('DisruptRadar — Projeção mensal'!B6),1)))),0,IF('DisruptRadar — Projeção men (2)'!B13="","",'DisruptRadar — Projeção men (2)'!B13)))+'DisruptRadar — Projeção men (2)'!C10 -> -655 | D13: =IF(IF(IF(IF(ISERROR(DATE(2027,3,1)=DATE(YEAR('DisruptRadar — Projeção mensal'!B6),MONTH('DisruptRadar — Projeção mensal'!B6),1)),DATE(2027,3,1)=DATE(YEAR('DisruptRadar — Projeção mensal'!B6),MONTH('DisruptRadar — Projeção mensal'!B6),1),IF(DATE(YEAR('DisruptRadar — Projeção mensal'!B6),MONTH('DisruptRadar — Projeção mensal'!B6),1)="","",DATE(2027,3,1)=DATE(YEAR('DisruptRadar — Projeção mensal'!B6),MONTH('DisruptRadar — Projeção mensal'!B6),1)))="",FALSE,IF(ISERROR(DATE(2027,3,1)=DATE(YEAR('DisruptRadar — Projeção mensal'!B6),MONTH('DisruptRadar — Projeção mensal'!B6),1)),DATE(2027,3,1)=DATE(YEAR('DisruptRadar — Projeção mensal'!B6),MONTH('DisruptRadar — Projeção mensal'!B6),1),IF(DATE(YEAR('DisruptRadar — Projeção mensal'!B6),MONTH('DisruptRadar — Projeção mensal'!B6),1)="","",DATE(2027,3,1)=DATE(YEAR('DisruptRadar — Projeção mensal'!B6),MONTH('DisruptRadar — Projeção mensal'!B6),1)))),0,IF('DisruptRadar — Projeção men (2)'!C13="","",'DisruptRadar — Projeção men (2)'!C13))="",0,IF(IF(IF(ISERROR(DATE(2027,3,1)=DATE(YEAR('DisruptRadar — Projeção mensal'!B6),MONTH('DisruptRadar — Projeção mensal'!B6),1)),DATE(2027,3,1)=DATE(YEAR('DisruptRadar — Projeção mensal'!B6),MONTH('DisruptRadar — Projeção mensal'!B6),1),IF(DATE(YEAR('DisruptRadar — Projeção mensal'!B6),MONTH('DisruptRadar — Projeção mensal'!B6),1)="","",DATE(2027,3,1)=DATE(YEAR('DisruptRadar — Projeção mensal'!B6),MONTH('DisruptRadar — Projeção mensal'!B6),1)))="",FALSE,IF(ISERROR(DATE(2027,3,1)=DATE(YEAR('DisruptRadar — Projeção mensal'!B6),MONTH('DisruptRadar — Projeção mensal'!B6),1)),DATE(2027,3,1)=DATE(YEAR('DisruptRadar — Projeção mensal'!B6),MONTH('DisruptRadar — Projeção mensal'!B6),1),IF(DATE(YEAR('DisruptRadar — Projeção mensal'!B6),MONTH('DisruptRadar — Projeção mensal'!B6),1)="","",DATE(2027,3,1)=DATE(YEAR('DisruptRadar — Projeção mensal'!B6),MONTH('DisruptRadar — Projeção mensal'!B6),1)))),0,IF('DisruptRadar — Projeção men (2)'!C13="","",'DisruptRadar — Projeção men (2)'!C13)))+'DisruptRadar — Projeção men (2)'!D10 -> -534 | E13: =IF(IF(IF(IF(ISERROR(DATE(2027,4,1)=DATE(YEAR('DisruptRadar — Projeção mensal'!B6),MONTH('DisruptRadar — Projeção mensal'!B6),1)),DATE(2027,4,1)=DATE(YEAR('DisruptRadar — Projeção mensal'!B6),MONTH('DisruptRadar — Projeção mensal'!B6),1),IF(DATE(YEAR('DisruptRadar — Projeção mensal'!B6),MONTH('DisruptRadar — Projeção mensal'!B6),1)="","",DATE(2027,4,1)=DATE(YEAR('DisruptRadar — Projeção mensal'!B6),MONTH('DisruptRadar — Projeção mensal'!B6),1)))="",FALSE,IF(ISERROR(DATE(2027,4,1)=DATE(YEAR('DisruptRadar — Projeção mensal'!B6),MONTH('DisruptRadar — Projeção mensal'!B6),1)),DATE(2027,4,1)=DATE(YEAR('DisruptRadar — Projeção mensal'!B6),MONTH('DisruptRadar — Projeção mensal'!B6),1),IF(DATE(YEAR('DisruptRadar — Projeção mensal'!B6),MONTH('DisruptRadar — Projeção mensal'!B6),1)="","",DATE(2027,4,1)=DATE(YEAR('DisruptRadar — Projeção mensal'!B6),MONTH('DisruptRadar — Projeção mensal'!B6),1)))),0,IF('DisruptRadar — Projeção men (2)'!D13="","",'DisruptRadar — Projeção men (2)'!D13))="",0,IF(IF(IF(ISERROR(DATE(2027,4,1)=DATE(YEAR('DisruptRadar — Projeção mensal'!B6),MONTH('DisruptRadar — Projeção mensal'!B6),1)),DATE(2027,4,1)=DATE(YEAR('DisruptRadar — Projeção mensal'!B6),MONTH('DisruptRadar — Projeção mensal'!B6),1),IF(DATE(YEAR('DisruptRadar — Projeção mensal'!B6),MONTH('DisruptRadar — Projeção mensal'!B6),1)="","",DATE(2027,4,1)=DATE(YEAR('DisruptRadar — Projeção mensal'!B6),MONTH('DisruptRadar — Projeção mensal'!B6),1)))="",FALSE,IF(ISERROR(DATE(2027,4,1)=DATE(YEAR('DisruptRadar — Projeção mensal'!B6),MONTH('DisruptRadar — Projeção mensal'!B6),1)),DATE(2027,4,1)=DATE(YEAR('DisruptRadar — Projeção mensal'!B6),MONTH('DisruptRadar — Projeção mensal'!B6),1),IF(DATE(YEAR('DisruptRadar — Projeção mensal'!B6),MONTH('DisruptRadar — Projeção mensal'!B6),1)="","",DATE(2027,4,1)=DATE(YEAR('DisruptRadar — Projeção mensal'!B6),MONTH('DisruptRadar — Projeção mensal'!B6),1)))),0,IF('DisruptRadar — Projeção men (2)'!D13="","",'DisruptRadar — Projeção men (2)'!D13)))+'DisruptRadar — Projeção men (2)'!E10 -> -68 | F13: =IF(IF(IF(IF(ISERROR(DATE(2027,5,1)=DATE(YEAR('DisruptRadar — Projeção mensal'!B6),MONTH('DisruptRadar — Projeção mensal'!B6),1)),DATE(2027,5,1)=DATE(YEAR('DisruptRadar — Projeção mensal'!B6),MONTH('DisruptRadar — Projeção mensal'!B6),1),IF(DATE(YEAR('DisruptRadar — Projeção mensal'!B6),MONTH('DisruptRadar — Projeção mensal'!B6),1)="","",DATE(2027,5,1)=DATE(YEAR('DisruptRadar — Projeção mensal'!B6),MONTH('DisruptRadar — Projeção mensal'!B6),1)))="",FALSE,IF(ISERROR(DATE(2027,5,1)=DATE(YEAR('DisruptRadar — Projeção mensal'!B6),MONTH('DisruptRadar — Projeção mensal'!B6),1)),DATE(2027,5,1)=DATE(YEAR('DisruptRadar — Projeção mensal'!B6),MONTH('DisruptRadar — Projeção mensal'!B6),1),IF(DATE(YEAR('DisruptRadar — Projeção mensal'!B6),MONTH('DisruptRadar — Projeção mensal'!B6),1)="","",DATE(2027,5,1)=DATE(YEAR('DisruptRadar — Projeção mensal'!B6),MONTH('DisruptRadar — Projeção mensal'!B6),1)))),0,IF('DisruptRadar — Projeção men (2)'!E13="","",'DisruptRadar — Projeção men (2)'!E13))="",0,IF(IF(IF(ISERROR(DATE(2027,5,1)=DATE(YEAR('DisruptRadar — Projeção mensal'!B6),MONTH('DisruptRadar — Projeção mensal'!B6),1)),DATE(2027,5,1)=DATE(YEAR('DisruptRadar — Projeção mensal'!B6),MONTH('DisruptRadar — Projeção mensal'!B6),1),IF(DATE(YEAR('DisruptRadar — Projeção mensal'!B6),MONTH('DisruptRadar — Projeção mensal'!B6),1)="","",DATE(2027,5,1)=DATE(YEAR('DisruptRadar — Projeção mensal'!B6),MONTH('DisruptRadar — Projeção mensal'!B6),1)))="",FALSE,IF(ISERROR(DATE(2027,5,1)=DATE(YEAR('DisruptRadar — Projeção mensal'!B6),MONTH('DisruptRadar — Projeção mensal'!B6),1)),DATE(2027,5,1)=DATE(YEAR('DisruptRadar — Projeção mensal'!B6),MONTH('DisruptRadar — Projeção mensal'!B6),1),IF(DATE(YEAR('DisruptRadar — Projeção mensal'!B6),MONTH('DisruptRadar — Projeção mensal'!B6),1)="","",DATE(2027,5,1)=DATE(YEAR('DisruptRadar — Projeção mensal'!B6),MONTH('DisruptRadar — Projeção mensal'!B6),1)))),0,IF('DisruptRadar — Projeção men (2)'!E13="","",'DisruptRadar — Projeção men (2)'!E13)))+'DisruptRadar — Projeção men (2)'!F10 -> 812 | G13: =IF(IF(IF(IF(ISERROR(DATE(2027,6,1)=DATE(YEAR('DisruptRadar — Projeção mensal'!B6),MONTH('DisruptRadar — Projeção mensal'!B6),1)),DATE(2027,6,1)=DATE(YEAR('DisruptRadar — Projeção mensal'!B6),MONTH('DisruptRadar — Projeção mensal'!B6),1),IF(DATE(YEAR('DisruptRadar — Projeção mensal'!B6),MONTH('DisruptRadar — Projeção mensal'!B6),1)="","",DATE(2027,6,1)=DATE(YEAR('DisruptRadar — Projeção mensal'!B6),MONTH('DisruptRadar — Projeção mensal'!B6),1)))="",FALSE,IF(ISERROR(DATE(2027,6,1)=DATE(YEAR('DisruptRadar — Projeção mensal'!B6),MONTH('DisruptRadar — Projeção mensal'!B6),1)),DATE(2027,6,1)=DATE(YEAR('DisruptRadar — Projeção mensal'!B6),MONTH('DisruptRadar — Projeção mensal'!B6),1),IF(DATE(YEAR('DisruptRadar — Projeção mensal'!B6),MONTH('DisruptRadar — Projeção mensal'!B6),1)="","",DATE(2027,6,1)=DATE(YEAR('DisruptRadar — Projeção mensal'!B6),MONTH('DisruptRadar — Projeção mensal'!B6),1)))),0,IF('DisruptRadar — Projeção men (2)'!F13="","",'DisruptRadar — Projeção men (2)'!F13))="",0,IF(IF(IF(ISERROR(DATE(2027,6,1)=DATE(YEAR('DisruptRadar — Projeção mensal'!B6),MONTH('DisruptRadar — Projeção mensal'!B6),1)),DATE(2027,6,1)=DATE(YEAR('DisruptRadar — Projeção mensal'!B6),MONTH('DisruptRadar — Projeção mensal'!B6),1),IF(DATE(YEAR('DisruptRadar — Projeção mensal'!B6),MONTH('DisruptRadar — Projeção mensal'!B6),1)="","",DATE(2027,6,1)=DATE(YEAR('DisruptRadar — Projeção mensal'!B6),MONTH('DisruptRadar — Projeção mensal'!B6),1)))="",FALSE,IF(ISERROR(DATE(2027,6,1)=DATE(YEAR('DisruptRadar — Projeção mensal'!B6),MONTH('DisruptRadar — Projeção mensal'!B6),1)),DATE(2027,6,1)=DATE(YEAR('DisruptRadar — Projeção mensal'!B6),MONTH('DisruptRadar — Projeção mensal'!B6),1),IF(DATE(YEAR('DisruptRadar — Projeção mensal'!B6),MONTH('DisruptRadar — Projeção mensal'!B6),1)="","",DATE(2027,6,1)=DATE(YEAR('DisruptRadar — Projeção mensal'!B6),MONTH('DisruptRadar — Projeção mensal'!B6),1)))),0,IF('DisruptRadar — Projeção men (2)'!F13="","",'DisruptRadar — Projeção men (2)'!F13)))+'DisruptRadar — Projeção men (2)'!G10 -> 2106 | H13: =IF(IF(IF(IF(ISERROR(DATE(2027,7,1)=DATE(YEAR('DisruptRadar — Projeção mensal'!B6),MONTH('DisruptRadar — Projeção mensal'!B6),1)),DATE(2027,7,1)=DATE(YEAR('DisruptRadar — Projeção mensal'!B6),MONTH('DisruptRadar — Projeção mensal'!B6),1),IF(DATE(YEAR('DisruptRadar — Projeção mensal'!B6),MONTH('DisruptRadar — Projeção mensal'!B6),1)="","",DATE(2027,7,1)=DATE(YEAR('DisruptRadar — Projeção mensal'!B6),MONTH('DisruptRadar — Projeção mensal'!B6),1)))="",FALSE,IF(ISERROR(DATE(2027,7,1)=DATE(YEAR('DisruptRadar — Projeção mensal'!B6),MONTH('DisruptRadar — Projeção mensal'!B6),1)),DATE(2027,7,1)=DATE(YEAR('DisruptRadar — Projeção mensal'!B6),MONTH('DisruptRadar — Projeção mensal'!B6),1),IF(DATE(YEAR('DisruptRadar — Projeção mensal'!B6),MONTH('DisruptRadar — Projeção mensal'!B6),1)="","",DATE(2027,7,1)=DATE(YEAR('DisruptRadar — Projeção mensal'!B6),MONTH('DisruptRadar — Projeção mensal'!B6),1)))),0,IF('DisruptRadar — Projeção men (2)'!G13="","",'DisruptRadar — Projeção men (2)'!G13))="",0,IF(IF(IF(ISERROR(DATE(2027,7,1)=DATE(YEAR('DisruptRadar — Projeção mensal'!B6),MONTH('DisruptRadar — Projeção mensal'!B6),1)),DATE(2027,7,1)=DATE(YEAR('DisruptRadar — Projeção mensal'!B6),MONTH('DisruptRadar — Projeção mensal'!B6),1),IF(DATE(YEAR('DisruptRadar — Projeção mensal'!B6),MONTH('DisruptRadar — Projeção mensal'!B6),1)="","",DATE(2027,7,1)=DATE(YEAR('DisruptRadar — Projeção mensal'!B6),MONTH('DisruptRadar — Projeção mensal'!B6),1)))="",FALSE,IF(ISERROR(DATE(2027,7,1)=DATE(YEAR('DisruptRadar — Projeção mensal'!B6),MONTH('DisruptRadar — Projeção mensal'!B6),1)),DATE(2027,7,1)=DATE(YEAR('DisruptRadar — Projeção mensal'!B6),MONTH('DisruptRadar — Projeção mensal'!B6),1),IF(DATE(YEAR('DisruptRadar — Projeção mensal'!B6),MONTH('DisruptRadar — Projeção mensal'!B6),1)="","",DATE(2027,7,1)=DATE(YEAR('DisruptRadar — Projeção mensal'!B6),MONTH('DisruptRadar — Projeção mensal'!B6),1)))),0,IF('DisruptRadar — Projeção men (2)'!G13="","",'DisruptRadar — Projeção men (2)'!G13)))+'DisruptRadar — Projeção men (2)'!H10 -> 3814 | I13: =IF(IF(IF(IF(ISERROR(DATE(2027,8,1)=DATE(YEAR('DisruptRadar — Projeção mensal'!B6),MONTH('DisruptRadar — Projeção mensal'!B6),1)),DATE(2027,8,1)=DATE(YEAR('DisruptRadar — Projeção mensal'!B6),MONTH('DisruptRadar — Projeção mensal'!B6),1),IF(DATE(YEAR('DisruptRadar — Projeção mensal'!B6),MONTH('DisruptRadar — Projeção mensal'!B6),1)="","",DATE(2027,8,1)=DATE(YEAR('DisruptRadar — Projeção mensal'!B6),MONTH('DisruptRadar — Projeção mensal'!B6),1)))="",FALSE,IF(ISERROR(DATE(2027,8,1)=DATE(YEAR('DisruptRadar — Projeção mensal'!B6),MONTH('DisruptRadar — Projeção mensal'!B6),1)),DATE(2027,8,1)=DATE(YEAR('DisruptRadar — Projeção mensal'!B6),MONTH('DisruptRadar — Projeção mensal'!B6),1),IF(DATE(YEAR('DisruptRadar — Projeção mensal'!B6),MONTH('DisruptRadar — Projeção mensal'!B6),1)="","",DATE(2027,8,1)=DATE(YEAR('DisruptRadar — Projeção mensal'!B6),MONTH('DisruptRadar — Projeção mensal'!B6),1)))),0,IF('DisruptRadar — Projeção men (2)'!H13="","",'DisruptRadar — Projeção men (2)'!H13))="",0,IF(IF(IF(ISERROR(DATE(2027,8,1)=DATE(YEAR('DisruptRadar — Projeção mensal'!B6),MONTH('DisruptRadar — Projeção mensal'!B6),1)),DATE(2027,8,1)=DATE(YEAR('DisruptRadar — Projeção mensal'!B6),MONTH('DisruptRadar — Projeção mensal'!B6),1),IF(DATE(YEAR('DisruptRadar — Projeção mensal'!B6),MONTH('DisruptRadar — Projeção mensal'!B6),1)="","",DATE(2027,8,1)=DATE(YEAR('DisruptRadar — Projeção mensal'!B6),MONTH('DisruptRadar — Projeção mensal'!B6),1)))="",FALSE,IF(ISERROR(DATE(2027,8,1)=DATE(YEAR('DisruptRadar — Projeção mensal'!B6),MONTH('DisruptRadar — Projeção mensal'!B6),1)),DATE(2027,8,1)=DATE(YEAR('DisruptRadar — Projeção mensal'!B6),MONTH('DisruptRadar — Projeção mensal'!B6),1),IF(DATE(YEAR('DisruptRadar — Projeção mensal'!B6),MONTH('DisruptRadar — Projeção mensal'!B6),1)="","",DATE(2027,8,1)=DATE(YEAR('DisruptRadar — Projeção mensal'!B6),MONTH('DisruptRadar — Projeção mensal'!B6),1)))),0,IF('DisruptRadar — Projeção men (2)'!H13="","",'DisruptRadar — Projeção men (2)'!H13)))+'DisruptRadar — Projeção men (2)'!I10 -> 5936 | J13: =IF(IF(IF(IF(ISERROR(DATE(2027,9,1)=DATE(YEAR('DisruptRadar — Projeção mensal'!B6),MONTH('DisruptRadar — Projeção mensal'!B6),1)),DATE(2027,9,1)=DATE(YEAR('DisruptRadar — Projeção mensal'!B6),MONTH('DisruptRadar — Projeção mensal'!B6),1),IF(DATE(YEAR('DisruptRadar — Projeção mensal'!B6),MONTH('DisruptRadar — Projeção mensal'!B6),1)="","",DATE(2027,9,1)=DATE(YEAR('DisruptRadar — Projeção mensal'!B6),MONTH('DisruptRadar — Projeção mensal'!B6),1)))="",FALSE,IF(ISERROR(DATE(2027,9,1)=DATE(YEAR('DisruptRadar — Projeção mensal'!B6),MONTH('DisruptRadar — Projeção mensal'!B6),1)),DATE(2027,9,1)=DATE(YEAR('DisruptRadar — Projeção mensal'!B6),MONTH('DisruptRadar — Projeção mensal'!B6),1),IF(DATE(YEAR('DisruptRadar — Projeção mensal'!B6),MONTH('DisruptRadar — Projeção mensal'!B6),1)="","",DATE(2027,9,1)=DATE(YEAR('DisruptRadar — Projeção mensal'!B6),MONTH('DisruptRadar — Projeção mensal'!B6),1)))),0,IF('DisruptRadar — Projeção men (2)'!I13="","",'DisruptRadar — Projeção men (2)'!I13))="",0,IF(IF(IF(ISERROR(DATE(2027,9,1)=DATE(YEAR('DisruptRadar — Projeção mensal'!B6),MONTH('DisruptRadar — Projeção mensal'!B6),1)),DATE(2027,9,1)=DATE(YEAR('DisruptRadar — Projeção mensal'!B6),MONTH('DisruptRadar — Projeção mensal'!B6),1),IF(DATE(YEAR('DisruptRadar — Projeção mensal'!B6),MONTH('DisruptRadar — Projeção mensal'!B6),1)="","",DATE(2027,9,1)=DATE(YEAR('DisruptRadar — Projeção mensal'!B6),MONTH('DisruptRadar — Projeção mensal'!B6),1)))="",FALSE,IF(ISERROR(DATE(2027,9,1)=DATE(YEAR('DisruptRadar — Projeção mensal'!B6),MONTH('DisruptRadar — Projeção mensal'!B6),1)),DATE(2027,9,1)=DATE(YEAR('DisruptRadar — Projeção mensal'!B6),MONTH('DisruptRadar — Projeção mensal'!B6),1),IF(DATE(YEAR('DisruptRadar — Projeção mensal'!B6),MONTH('DisruptRadar — Projeção mensal'!B6),1)="","",DATE(2027,9,1)=DATE(YEAR('DisruptRadar — Projeção mensal'!B6),MONTH('DisruptRadar — Projeção mensal'!B6),1)))),0,IF('DisruptRadar — Projeção men (2)'!I13="","",'DisruptRadar — Projeção men (2)'!I13)))+'DisruptRadar — Projeção men (2)'!J10 -> 8196 | K13: =IF(IF(IF(IF(ISERROR(DATE(2027,10,1)=DATE(YEAR('DisruptRadar — Projeção mensal'!B6),MONTH('DisruptRadar — Projeção mensal'!B6),1)),DATE(2027,10,1)=DATE(YEAR('DisruptRadar — Projeção mensal'!B6),MONTH('DisruptRadar — Projeção mensal'!B6),1),IF(DATE(YEAR('DisruptRadar — Projeção mensal'!B6),MONTH('DisruptRadar — Projeção mensal'!B6),1)="","",DATE(2027,10,1)=DATE(YEAR('DisruptRadar — Projeção mensal'!B6),MONTH('DisruptRadar — Projeção mensal'!B6),1)))="",FALSE,IF(ISERROR(DATE(2027,10,1)=DATE(YEAR('DisruptRadar — Projeção mensal'!B6),MONTH('DisruptRadar — Projeção mensal'!B6),1)),DATE(2027,10,1)=DATE(YEAR('DisruptRadar — Projeção mensal'!B6),MONTH('DisruptRadar — Projeção mensal'!B6),1),IF(DATE(YEAR('DisruptRadar — Projeção mensal'!B6),MONTH('DisruptRadar — Projeção mensal'!B6),1)="","",DATE(2027,10,1)=DATE(YEAR('DisruptRadar — Projeção mensal'!B6),MONTH('DisruptRadar — Projeção mensal'!B6),1)))),0,IF('DisruptRadar — Projeção men (2)'!J13="","",'DisruptRadar — Projeção men (2)'!J13))="",0,IF(IF(IF(ISERROR(DATE(2027,10,1)=DATE(YEAR('DisruptRadar — Projeção mensal'!B6),MONTH('DisruptRadar — Projeção mensal'!B6),1)),DATE(2027,10,1)=DATE(YEAR('DisruptRadar — Projeção mensal'!B6),MONTH('DisruptRadar — Projeção mensal'!B6),1),IF(DATE(YEAR('DisruptRadar — Projeção mensal'!B6),MONTH('DisruptRadar — Projeção mensal'!B6),1)="","",DATE(2027,10,1)=DATE(YEAR('DisruptRadar — Projeção mensal'!B6),MONTH('DisruptRadar — Projeção mensal'!B6),1)))="",FALSE,IF(ISERROR(DATE(2027,10,1)=DATE(YEAR('DisruptRadar — Projeção mensal'!B6),MONTH('DisruptRadar — Projeção mensal'!B6),1)),DATE(2027,10,1)=DATE(YEAR('DisruptRadar — Projeção mensal'!B6),MONTH('DisruptRadar — Projeção mensal'!B6),1),IF(DATE(YEAR('DisruptRadar — Projeção mensal'!B6),MONTH('DisruptRadar — Projeção mensal'!B6),1)="","",DATE(2027,10,1)=DATE(YEAR('DisruptRadar — Projeção mensal'!B6),MONTH('DisruptRadar — Projeção mensal'!B6),1)))),0,IF('DisruptRadar — Projeção men (2)'!J13="","",'DisruptRadar — Projeção men (2)'!J13)))+'DisruptRadar — Projeção men (2)'!K10 -> 10456 | L13: =IF(IF(IF(IF(ISERROR(DATE(2027,11,1)=DATE(YEAR('DisruptRadar — Projeção mensal'!B6),MONTH('DisruptRadar — Projeção mensal'!B6),1)),DATE(2027,11,1)=DATE(YEAR('DisruptRadar — Projeção mensal'!B6),MONTH('DisruptRadar — Projeção mensal'!B6),1),IF(DATE(YEAR('DisruptRadar — Projeção mensal'!B6),MONTH('DisruptRadar — Projeção mensal'!B6),1)="","",DATE(2027,11,1)=DATE(YEAR('DisruptRadar — Projeção mensal'!B6),MONTH('DisruptRadar — Projeção mensal'!B6),1)))="",FALSE,IF(ISERROR(DATE(2027,11,1)=DATE(YEAR('DisruptRadar — Projeção mensal'!B6),MONTH('DisruptRadar — Projeção mensal'!B6),1)),DATE(2027,11,1)=DATE(YEAR('DisruptRadar — Projeção mensal'!B6),MONTH('DisruptRadar — Projeção mensal'!B6),1),IF(DATE(YEAR('DisruptRadar — Projeção mensal'!B6),MONTH('DisruptRadar — Projeção mensal'!B6),1)="","",DATE(2027,11,1)=DATE(YEAR('DisruptRadar — Projeção mensal'!B6),MONTH('DisruptRadar — Projeção mensal'!B6),1)))),0,IF('DisruptRadar — Projeção men (2)'!K13="","",'DisruptRadar — Projeção men (2)'!K13))="",0,IF(IF(IF(ISERROR(DATE(2027,11,1)=DATE(YEAR('DisruptRadar — Projeção mensal'!B6),MONTH('DisruptRadar — Projeção mensal'!B6),1)),DATE(2027,11,1)=DATE(YEAR('DisruptRadar — Projeção mensal'!B6),MONTH('DisruptRadar — Projeção mensal'!B6),1),IF(DATE(YEAR('DisruptRadar — Projeção mensal'!B6),MONTH('DisruptRadar — Projeção mensal'!B6),1)="","",DATE(2027,11,1)=DATE(YEAR('DisruptRadar — Projeção mensal'!B6),MONTH('DisruptRadar — Projeção mensal'!B6),1)))="",FALSE,IF(ISERROR(DATE(2027,11,1)=DATE(YEAR('DisruptRadar — Projeção mensal'!B6),MONTH('DisruptRadar — Projeção mensal'!B6),1)),DATE(2027,11,1)=DATE(YEAR('DisruptRadar — Projeção mensal'!B6),MONTH('DisruptRadar — Projeção mensal'!B6),1),IF(DATE(YEAR('DisruptRadar — Projeção mensal'!B6),MONTH('DisruptRadar — Projeção mensal'!B6),1)="","",DATE(2027,11,1)=DATE(YEAR('DisruptRadar — Projeção mensal'!B6),MONTH('DisruptRadar — Projeção mensal'!B6),1)))),0,IF('DisruptRadar — Projeção men (2)'!K13="","",'DisruptRadar — Projeção men (2)'!K13)))+'DisruptRadar — Projeção men (2)'!L10 -> 12716 | M13: =IF(IF(IF(IF(ISERROR(DATE(2027,12,1)=DATE(YEAR('DisruptRadar — Projeção mensal'!B6),MONTH('DisruptRadar — Projeção mensal'!B6),1)),DATE(2027,12,1)=DATE(YEAR('DisruptRadar — Projeção mensal'!B6),MONTH('DisruptRadar — Projeção mensal'!B6),1),IF(DATE(YEAR('DisruptRadar — Projeção mensal'!B6),MONTH('DisruptRadar — Projeção mensal'!B6),1)="","",DATE(2027,12,1)=DATE(YEAR('DisruptRadar — Projeção mensal'!B6),MONTH('DisruptRadar — Projeção mensal'!B6),1)))="",FALSE,IF(ISERROR(DATE(2027,12,1)=DATE(YEAR('DisruptRadar — Projeção mensal'!B6),MONTH('DisruptRadar — Projeção mensal'!B6),1)),DATE(2027,12,1)=DATE(YEAR('DisruptRadar — Projeção mensal'!B6),MONTH('DisruptRadar — Projeção mensal'!B6),1),IF(DATE(YEAR('DisruptRadar — Projeção mensal'!B6),MONTH('DisruptRadar — Projeção mensal'!B6),1)="","",DATE(2027,12,1)=DATE(YEAR('DisruptRadar — Projeção mensal'!B6),MONTH('DisruptRadar — Projeção mensal'!B6),1)))),0,IF('DisruptRadar — Projeção men (2)'!L13="","",'DisruptRadar — Projeção men (2)'!L13))="",0,IF(IF(IF(ISERROR(DATE(2027,12,1)=DATE(YEAR('DisruptRadar — Projeção mensal'!B6),MONTH('DisruptRadar — Projeção mensal'!B6),1)),DATE(2027,12,1)=DATE(YEAR('DisruptRadar — Projeção mensal'!B6),MONTH('DisruptRadar — Projeção mensal'!B6),1),IF(DATE(YEAR('DisruptRadar — Projeção mensal'!B6),MONTH('DisruptRadar — Projeção mensal'!B6),1)="","",DATE(2027,12,1)=DATE(YEAR('DisruptRadar — Projeção mensal'!B6),MONTH('DisruptRadar — Projeção mensal'!B6),1)))="",FALSE,IF(ISERROR(DATE(2027,12,1)=DATE(YEAR('DisruptRadar — Projeção mensal'!B6),MONTH('DisruptRadar — Projeção mensal'!B6),1)),DATE(2027,12,1)=DATE(YEAR('DisruptRadar — Projeção mensal'!B6),MONTH('DisruptRadar — Projeção mensal'!B6),1),IF(DATE(YEAR('DisruptRadar — Projeção mensal'!B6),MONTH('DisruptRadar — Projeção mensal'!B6),1)="","",DATE(2027,12,1)=DATE(YEAR('DisruptRadar — Projeção mensal'!B6),MONTH('DisruptRadar — Projeção mensal'!B6),1)))),0,IF('DisruptRadar — Projeção men (2)'!L13="","",'DisruptRadar — Projeção men (2)'!L13)))+'DisruptRadar — Projeção men (2)'!M10 -> 14976
A14: Verificação de caixa — projeção Base (EUR) | B14: ='DisruptRadar — Projeção men (2)'!B12-('DisruptRadar Business Plan · Pr'!B7+'DisruptRadar — Projeção men (2)'!B13) -> 0 | C14: ='DisruptRadar — Projeção men (2)'!C12-('DisruptRadar Business Plan · Pr'!B7+'DisruptRadar — Projeção men (2)'!C13) -> 0 | D14: ='DisruptRadar — Projeção men (2)'!D12-('DisruptRadar Business Plan · Pr'!B7+'DisruptRadar — Projeção men (2)'!D13) -> 0 | E14: ='DisruptRadar — Projeção men (2)'!E12-('DisruptRadar Business Plan · Pr'!B7+'DisruptRadar — Projeção men (2)'!E13) -> 0 | F14: ='DisruptRadar — Projeção men (2)'!F12-('DisruptRadar Business Plan · Pr'!B7+'DisruptRadar — Projeção men (2)'!F13) -> 0 | G14: ='DisruptRadar — Projeção men (2)'!G12-('DisruptRadar Business Plan · Pr'!B7+'DisruptRadar — Projeção men (2)'!G13) -> 0 | H14: ='DisruptRadar — Projeção men (2)'!H12-('DisruptRadar Business Plan · Pr'!B7+'DisruptRadar — Projeção men (2)'!H13) -> 0 | I14: ='DisruptRadar — Projeção men (2)'!I12-('DisruptRadar Business Plan · Pr'!B7+'DisruptRadar — Projeção men (2)'!I13) -> 0 | J14: ='DisruptRadar — Projeção men (2)'!J12-('DisruptRadar Business Plan · Pr'!B7+'DisruptRadar — Projeção men (2)'!J13) -> 0 | K14: ='DisruptRadar — Projeção men (2)'!K12-('DisruptRadar Business Plan · Pr'!B7+'DisruptRadar — Projeção men (2)'!K13) -> 0 | L14: ='DisruptRadar — Projeção men (2)'!L12-('DisruptRadar Business Plan · Pr'!B7+'DisruptRadar — Projeção men (2)'!L13) -> 0 | M14: ='DisruptRadar — Projeção men (2)'!M12-('DisruptRadar Business Plan · Pr'!B7+'DisruptRadar — Projeção men (2)'!M13) -> 0

Sheet DisruptRadar — Projeção men (3)
A1: DisruptRadar — Projeção mensal · Reconciliação anual Base com a matriz
A2: Financial model (2 pages) · Base
A4: Variable / dimension | B4: Value
A5: Clientes-mês — projeção Base | B5: =SUM('DisruptRadar — Projeção men (2)'!B5,'DisruptRadar — Projeção men (2)'!C5,'DisruptRadar — Projeção men (2)'!D5,'DisruptRadar — Projeção men (2)'!E5,'DisruptRadar — Projeção men (2)'!F5,'DisruptRadar — Projeção men (2)'!G5,'DisruptRadar — Projeção men (2)'!H5,'DisruptRadar — Projeção men (2)'!I5,'DisruptRadar — Projeção men (2)'!J5,'DisruptRadar — Projeção men (2)'!K5,'DisruptRadar — Projeção men (2)'!L5,'DisruptRadar — Projeção men (2)'!M5) -> 304
A6: Receita anual — projeção Base (EUR) | B6: =SUM('DisruptRadar — Projeção men (2)'!B6,'DisruptRadar — Projeção men (2)'!C6,'DisruptRadar — Projeção men (2)'!D6,'DisruptRadar — Projeção men (2)'!E6,'DisruptRadar — Projeção men (2)'!F6,'DisruptRadar — Projeção men (2)'!G6,'DisruptRadar — Projeção men (2)'!H6,'DisruptRadar — Projeção men (2)'!I6,'DisruptRadar — Projeção men (2)'!J6,'DisruptRadar — Projeção men (2)'!K6,'DisruptRadar — Projeção men (2)'!L6,'DisruptRadar — Projeção men (2)'!M6) -> 30096
A7: Entrega anual — projeção Base (EUR) | B7: =SUM('DisruptRadar — Projeção men (2)'!B7,'DisruptRadar — Projeção men (2)'!C7,'DisruptRadar — Projeção men (2)'!D7,'DisruptRadar — Projeção men (2)'!E7,'DisruptRadar — Projeção men (2)'!F7,'DisruptRadar — Projeção men (2)'!G7,'DisruptRadar — Projeção men (2)'!H7,'DisruptRadar — Projeção men (2)'!I7,'DisruptRadar — Projeção men (2)'!J7,'DisruptRadar — Projeção men (2)'!K7,'DisruptRadar — Projeção men (2)'!L7,'DisruptRadar — Projeção men (2)'!M7) -> 9120
A8: Fixos anuais calculados — projeção Base (EUR) | B8: =SUM('DisruptRadar — Projeção men (2)'!B8,'DisruptRadar — Projeção men (2)'!C8,'DisruptRadar — Projeção men (2)'!D8,'DisruptRadar — Projeção men (2)'!E8,'DisruptRadar — Projeção men (2)'!F8,'DisruptRadar — Projeção men (2)'!G8,'DisruptRadar — Projeção men (2)'!H8,'DisruptRadar — Projeção men (2)'!I8,'DisruptRadar — Projeção men (2)'!J8,'DisruptRadar — Projeção men (2)'!K8,'DisruptRadar — Projeção men (2)'!L8,'DisruptRadar — Projeção men (2)'!M8) -> 6000
A9: Custos anuais — projeção Base (EUR) | B9: =SUM('DisruptRadar — Projeção men (2)'!B9,'DisruptRadar — Projeção men (2)'!C9,'DisruptRadar — Projeção men (2)'!D9,'DisruptRadar — Projeção men (2)'!E9,'DisruptRadar — Projeção men (2)'!F9,'DisruptRadar — Projeção men (2)'!G9,'DisruptRadar — Projeção men (2)'!H9,'DisruptRadar — Projeção men (2)'!I9,'DisruptRadar — Projeção men (2)'!J9,'DisruptRadar — Projeção men (2)'!K9,'DisruptRadar — Projeção men (2)'!L9,'DisruptRadar — Projeção men (2)'!M9) -> 15120
A10: EBITDA anual — projeção Base (EUR) | B10: =SUM('DisruptRadar — Projeção men (2)'!B10,'DisruptRadar — Projeção men (2)'!C10,'DisruptRadar — Projeção men (2)'!D10,'DisruptRadar — Projeção men (2)'!E10,'DisruptRadar — Projeção men (2)'!F10,'DisruptRadar — Projeção men (2)'!G10,'DisruptRadar — Projeção men (2)'!H10,'DisruptRadar — Projeção men (2)'!I10,'DisruptRadar — Projeção men (2)'!J10,'DisruptRadar — Projeção men (2)'!K10,'DisruptRadar — Projeção men (2)'!L10,'DisruptRadar — Projeção men (2)'!M10) -> 14976
A11: Caixa mínima — projeção Base (EUR) | B11: =MIN('DisruptRadar — Projeção men (2)'!B12,'DisruptRadar — Projeção men (2)'!C12,'DisruptRadar — Projeção men (2)'!D12,'DisruptRadar — Projeção men (2)'!E12,'DisruptRadar — Projeção men (2)'!F12,'DisruptRadar — Projeção men (2)'!G12,'DisruptRadar — Projeção men (2)'!H12,'DisruptRadar — Projeção men (2)'!I12,'DisruptRadar — Projeção men (2)'!J12,'DisruptRadar — Projeção men (2)'!K12,'DisruptRadar — Projeção men (2)'!L12,'DisruptRadar — Projeção men (2)'!M12) -> 19345
A12: Caixa ao fim do ano — projeção Base (EUR) | B12: =IF('DisruptRadar — Projeção men (2)'!M12="","",'DisruptRadar — Projeção men (2)'!M12) -> 34976
A13: Diferença de receita vs matriz Base (EUR) | B13: ='DisruptRadar — Projeção men (3)'!B6-'DisruptRadar Business Plan · Ma'!B6 -> 0
A14: Diferença de custos vs matriz Base (EUR) | B14: ='DisruptRadar — Projeção men (3)'!B9-'DisruptRadar Business Plan · Ma'!B7 -> 0
A15: Diferença de EBITDA vs matriz Base (EUR) | B15: ='DisruptRadar — Projeção men (3)'!B10-'DisruptRadar Business Plan · Ma'!B8 -> 0

Sheet DisruptRadar — Projeção men (4)
A1: DisruptRadar — Projeção mensal · Sensibilidade Base — fixos mensais
A2: Financial model (2 pages) · Base
A4: Variable / dimension | B4: Value | C4: Value > Base — fixos 300 €/mês | D4: Value > Base — fixos 400 €/mês | E4: Value > Base — fixos 500 €/mês
A5: Fixos anuais da projeção Base (EUR) | B5: ='DisruptRadar — Projeção mensal'!B5 -> 6000 | C5: =3600 -> 3600 | D5: =4800 -> 4800 | E5: =6000 -> 6000
A6: Custos anuais — projeção Base (EUR) | B6: =SUM('DisruptRadar — Projeção men (2)'!B9,'DisruptRadar — Projeção men (2)'!C9,'DisruptRadar — Projeção men (2)'!D9,'DisruptRadar — Projeção men (2)'!E9,'DisruptRadar — Projeção men (2)'!F9,'DisruptRadar — Projeção men (2)'!G9,'DisruptRadar — Projeção men (2)'!H9,'DisruptRadar — Projeção men (2)'!I9,'DisruptRadar — Projeção men (2)'!J9,'DisruptRadar — Projeção men (2)'!K9,'DisruptRadar — Projeção men (2)'!L9,'DisruptRadar — Projeção men (2)'!M9) -> 15120 | C6: =SUM('Model inputs'!C33,'Model inputs'!D33,'Model inputs'!E33,'Model inputs'!F33,'Model inputs'!G33,'Model inputs'!H33,'Model inputs'!I33,'Model inputs'!J33,'Model inputs'!K33,'Model inputs'!L33,'Model inputs'!M33,'Model inputs'!N33) -> 12720 | D6: =SUM('Model inputs'!C32,'Model inputs'!D32,'Model inputs'!E32,'Model inputs'!F32,'Model inputs'!G32,'Model inputs'!H32,'Model inputs'!I32,'Model inputs'!J32,'Model inputs'!K32,'Model inputs'!L32,'Model inputs'!M32,'Model inputs'!N32) -> 13920 | E6: =SUM('Model inputs'!C34,'Model inputs'!D34,'Model inputs'!E34,'Model inputs'!F34,'Model inputs'!G34,'Model inputs'!H34,'Model inputs'!I34,'Model inputs'!J34,'Model inputs'!K34,'Model inputs'!L34,'Model inputs'!M34,'Model inputs'!N34) -> 15120
A7: EBITDA anual — projeção Base (EUR) | B7: =SUM('DisruptRadar — Projeção men (2)'!B10,'DisruptRadar — Projeção men (2)'!C10,'DisruptRadar — Projeção men (2)'!D10,'DisruptRadar — Projeção men (2)'!E10,'DisruptRadar — Projeção men (2)'!F10,'DisruptRadar — Projeção men (2)'!G10,'DisruptRadar — Projeção men (2)'!H10,'DisruptRadar — Projeção men (2)'!I10,'DisruptRadar — Projeção men (2)'!J10,'DisruptRadar — Projeção men (2)'!K10,'DisruptRadar — Projeção men (2)'!L10,'DisruptRadar — Projeção men (2)'!M10) -> 14976 | C7: =SUM('Model inputs'!C45,'Model inputs'!D45,'Model inputs'!E45,'Model inputs'!F45,'Model inputs'!G45,'Model inputs'!H45,'Model inputs'!I45,'Model inputs'!J45,'Model inputs'!K45,'Model inputs'!L45,'Model inputs'!M45,'Model inputs'!N45) -> 17376 | D7: =SUM('Model inputs'!C43,'Model inputs'!D43,'Model inputs'!E43,'Model inputs'!F43,'Model inputs'!G43,'Model inputs'!H43,'Model inputs'!I43,'Model inputs'!J43,'Model inputs'!K43,'Model inputs'!L43,'Model inputs'!M43,'Model inputs'!N43) -> 16176 | E7: =SUM('Model inputs'!C48,'Model inputs'!D48,'Model inputs'!E48,'Model inputs'!F48,'Model inputs'!G48,'Model inputs'!H48,'Model inputs'!I48,'Model inputs'!J48,'Model inputs'!K48,'Model inputs'!L48,'Model inputs'!M48,'Model inputs'!N48) -> 14976
A8: Caixa mínima — projeção Base (EUR) | B8: =MIN('DisruptRadar — Projeção men (2)'!B12,'DisruptRadar — Projeção men (2)'!C12,'DisruptRadar — Projeção men (2)'!D12,'DisruptRadar — Projeção men (2)'!E12,'DisruptRadar — Projeção men (2)'!F12,'DisruptRadar — Projeção men (2)'!G12,'DisruptRadar — Projeção men (2)'!H12,'DisruptRadar — Projeção men (2)'!I12,'DisruptRadar — Projeção men (2)'!J12,'DisruptRadar — Projeção men (2)'!K12,'DisruptRadar — Projeção men (2)'!L12,'DisruptRadar — Projeção men (2)'!M12) -> 19345 | C8: =MIN('Model inputs'!C9,'Model inputs'!D9,'Model inputs'!E9,'Model inputs'!F9,'Model inputs'!G9,'Model inputs'!H9,'Model inputs'!I9,'Model inputs'!J9,'Model inputs'!K9,'Model inputs'!L9,'Model inputs'!M9,'Model inputs'!N9) -> 19745 | D8: =MIN('Model inputs'!C8,'Model inputs'!D8,'Model inputs'!E8,'Model inputs'!F8,'Model inputs'!G8,'Model inputs'!H8,'Model inputs'!I8,'Model inputs'!J8,'Model inputs'!K8,'Model inputs'!L8,'Model inputs'!M8,'Model inputs'!N8) -> 19545 | E8: =MIN('Model inputs'!C10,'Model inputs'!D10,'Model inputs'!E10,'Model inputs'!F10,'Model inputs'!G10,'Model inputs'!H10,'Model inputs'!I10,'Model inputs'!J10,'Model inputs'!K10,'Model inputs'!L10,'Model inputs'!M10,'Model inputs'!N10) -> 19345
A9: Caixa ao fim do ano — projeção Base (EUR) | B9: =IF('DisruptRadar — Projeção men (2)'!M12="","",'DisruptRadar — Projeção men (2)'!M12) -> 34976 | C9: =IF('Model inputs'!N9="","",'Model inputs'!N9) -> 37376 | D9: =IF('Model inputs'!N8="","",'Model inputs'!N8) -> 36176 | E9: =IF('Model inputs'!N10="","",'Model inputs'!N10) -> 34976

Sheet DisruptRadar — Projeção men (5)
A1: DisruptRadar — Projeção mensal · Sensibilidade completa — preço Pro e fixos
A2: Financial model (2 pages) · Base
A4: Variable / dimension | B4: Value | C4: Value > Base — fixos 300 €/mês | D4: Value > Base — fixos 400 €/mês | E4: Value > Teste Pro 109 € — fixos 300 €/mês | F4: Value > Teste Pro 109 € — fixos 400 €/mês | G4: Value > Teste Pro 109 € — fixos 500 €/mês | H4: Value > Teste Pro 119 € — fixos 300 €/mês | I4: Value > Teste Pro 119 € — fixos 400 €/mês | J4: Value > Teste Pro 119 € — fixos 500 €/mês
A5: Preço mensal Pro (EUR) | B5: =99 -> 99 | C5: =99 -> 99 | D5: =99 -> 99 | E5: =109 -> 109 | F5: =109 -> 109 | G5: =109 -> 109 | H5: =119 -> 119 | I5: =119 -> 119 | J5: =119 -> 119
A6: Fixos anuais da projeção Base (EUR) | B6: ='DisruptRadar — Projeção mensal'!B5 -> 6000 | C6: ='DisruptRadar — Projeção men (4)'!C5 -> 3600 | D6: ='DisruptRadar — Projeção men (4)'!D5 -> 4800 | E6: =3600 -> 3600 | F6: =4800 -> 4800 | G6: =6000 -> 6000 | H6: =3600 -> 3600 | I6: =4800 -> 4800 | J6: =6000 -> 6000
